Workbook

Sheet S1_Extracted_pairs
A1: pair_id | B1: study_id | C1: study | D1: year | E1: region | F1: sector | G1: functional_unit | H1: conventional | I1: alternative | J1: gwp_conventional | K1: gwp_alternative | L1: unit | M1: how_value_obtained | N1: sponsor_type | O1: sponsor_favours | P1: in_plastic_baseline_pool | Q1: source_url | R1: ratio | S1: ln_ratio | T1: alt_class | U1: comparability_caveat | W1: Note
A2: P01 | B2: S1 | C2: De Feo et al. (mineral water eco-efficiency) | D2: n/r | E2: Italy | F2: Bottled water | G2: 1000 L | H2: PET 0.5 L | I2: Glass one-way 0.5 L | J2: 198 | K2: 933 | L2: kg CO2e | M2: Reported directly in abstract | N2: Academic | O2: none | P2: yes | Q2: https://www.iris.unisa.it/handle/11386/4958656 | R2: =K2/J2 -> 4.7121212 | S2: =LN(R2) -> 1.5501382 | T2: Glass | W2: Columns R and S are now live formulas: ratio = K/J (alternative / conventional); ln_ratio = LN(ratio). Edit any GWP value in J or K and everything downstream recalculates.
A3: P02 | B3: S1 | C3: De Feo et al. (mineral water eco-efficiency) | D3: n/r | E3: Italy | F3: Bottled water | G3: 1000 L | H3: PET 0.5 L | I3: Aluminium can 0.33 L | J3: 198 | K3: 513 | L3: kg CO2e | M3: Reported directly in abstract | N3: Academic | O3: none | P3: yes | Q3: https://www.iris.unisa.it/handle/11386/4958656 | R3: =K3/J3 -> 2.5909091 | S3: =LN(R3) -> 0.95200881 | T3: Aluminium
A4: P03 | B4: S1 | C4: De Feo et al. (mineral water eco-efficiency) | D4: n/r | E4: Italy | F4: Bottled water | G4: 1000 L | H4: PET 0.5 L | I4: Aseptic carton 0.5 L | J4: 198 | K4: 170 | L4: kg CO2e | M4: Reported directly in abstract | N4: Academic | O4: none | P4: yes | Q4: https://www.iris.unisa.it/handle/11386/4958656 | R4: =K4/J4 -> 0.85858586 | S4: =LN(R4) -> -0.15246859 | T4: Carton
A5: P04 | B5: S2 | C5: Ferrara & De Feo | D5: 2023 | E5: Italy/EU destinations | F5: Olive oil | G5: 1000 L EVOO | H5: 100% recycled PET bottle | I5: Glass bottle | J5: 546.5 | K5: 963.5 | L5: kg CO2e | M5: Midpoint of reported ranges (PET 459-634; glass 790-1137) | N5: Academic | O5: none | P5: yes | Q5: https://www.iris.unisa.it/handle/11386/4840897 | R5: =K5/J5 -> 1.7630375 | S5: =LN(R5) -> 0.56703818 | T5: Glass
A6: P05 | B6: S3 | C6: NAPCOR LCA (conducted by Franklin Associates per trade press) | D6: 2023 | E6: USA | F6: Water/CSD | G6: per container (16.9 oz PET vs 12 oz can) | H6: PET bottle 16.9 oz | I6: Aluminium can 12 oz | J6: 26 | K6: 100 | L6: index (Al=100) | M6: PET reported as 74% lower than Al can; Al set to 100 | N6: Industry (PET trade body) | O6: PET | P6: yes | Q6: https://napcor.com/news/pet-plastic-bottles-have-a-significantly-lower-environmental-impact-compared-to-glass-bottles-and-aluminum-cans/ | R6: =K6/J6 -> 3.8461538 | S6: =LN(R6) -> 1.3470736 | T6: Aluminium | U6: Per container (index, Al can = 100); industry (PET trade body)
A7: P06 | B7: S4 | C7: Saudi Digital Library repository study (carbonated drinks) | D7: n/r | E7: n/r | F7: Carbonated drinks | G7: 1 L | H7: PET bottle | I7: Glass bottle | J7: 81.52 | K7: 425.43 | L7: g CO2e | M7: Reported directly in abstract | N7: Academic thesis/report | O7: none | P7: yes | Q7: https://drepo.sdl.edu.sa/items/b7c25e12-7df5-4086-a117-a66badf9f3b1 | R7: =K7/J7 -> 5.2187193 | S7: =LN(R7) -> 1.652252 | T7: Glass
A8: P07 | B8: S5 | C8: Carton-vs-bottle LCA summarised by iPoint (Combibloc carton) | D8: 2021 | E8: n/r (source discusses UK/US pints) | F8: Fresh milk | G8: 1 L | H8: PET bottle (disposable) | I8: Gable-top carton | J8: 154.5 | K8: 85 | L8: g CO2e | M8: Carton 85 g and 45% lower than PET -> PET=85/0.55 | N8: Industry-linked (carton product LCA; funder not verified) | O8: carton | P8: yes | Q8: https://go.ipoint-systems.com/blog/whats-the-greenest-1-l-packaging-two-powerful-lcas-give-the-answer | R8: =K8/J8 -> 0.55016181 | S8: =LN(R8) -> -0.59754284 | T8: Carton | U8: Derived from % difference; funder not verified
A9: P08 | B9: S5 | C9: Carton-vs-bottle LCA summarised by iPoint (Combibloc carton) | D9: 2021 | E9: n/r (source discusses UK/US pints) | F9: Fresh milk | G9: 1 L | H9: HDPE multilayer bottle | I9: Gable-top carton | J9: 128.8 | K9: 85 | L9: g CO2e | M9: Carton 85 g and 34% lower than HDPE -> HDPE=85/0.66 | N9: Industry-linked (carton product LCA; funder not verified) | O9: carton | P9: yes | Q9: https://go.ipoint-systems.com/blog/whats-the-greenest-1-l-packaging-two-powerful-lcas-give-the-answer | R9: =K9/J9 -> 0.65993789 | S9: =LN(R9) -> -0.41560956 | T9: Carton | U9: Derived from % difference; funder not verified
A10: P09 | B10: S6 | C10: Gallego-Schmid et al. | D10: 2019 | E10: EU | F10: Takeaway food container | G10: per container | H10: PP single-use | I10: Aluminium single-use | J10: 3 | K10: 2 | L10: index (EPS=1) | M10: EPS = 50% of Al and one-third of PP -> EPS=1 Al=2 PP=3 | N10: Academic | O10: none | P10: yes | Q10: https://www.manchester.ac.uk/discover/news/takeaway-containers--the-environmental-cost-of-packing-our-favourite-fast-foods | R10: =K10/J10 -> 0.66666667 | S10: =LN(R10) -> -0.40546511 | T10: Aluminium | U10: Index (EPS = 1) derived from stated percentages; per container
A11: P10 | B11: S7 | C11: TERI for Ball Corporation | D11: 2022 | E11: India | F11: Beer | G11: 1 L fill | H11: Glass bottle 650 mL | I11: Aluminium can 500 mL | J11: 3.52 | K11: 1 | L11: index (can=1) | M11: Text states glass GWP is 3.5x the can (Fig 16 = 352%) | N11: Industry (aluminium can maker) | O11: aluminium | P11: no (not plastic baseline) | Q11: https://www.teriin.org/sites/default/files/2022-06/Sustainable-Beverage-Packaging-Final-Report.pdf | R11: =K11/J11 -> 0.28409091 | S11: =LN(R11) -> -1.258461 | T11: Al vs glass (India) | U11: Industry (can maker); not pooled
A12: P11 | B12: S7 | C12: TERI for Ball Corporation | D12: 2022 | E12: India | F12: Beverages | G12: 1 L fill | H12: Glass bottle 200 mL | I12: Aluminium can 500 mL | J12: 5.26 | K12: 1 | L12: index (can=1) | M12: Text: 200 mL glass is 526% of the 500 mL can (Fig 9) | N12: Industry (aluminium can maker) | O12: aluminium | P12: no (not plastic baseline) | Q12: https://www.teriin.org/sites/default/files/2022-06/Sustainable-Beverage-Packaging-Final-Report.pdf | R12: =K12/J12 -> 0.19011407 | S12: =LN(R12) -> -1.660131 | T12: Al vs glass (India) | U12: Industry (can maker); not pooled
A13: P12 | B13: S8 | C13: Stefanini et al. (milk bottles) | D13: 2021 | E13: Italy | F13: Milk | G13: 1 L | H13: PET bottle | I13: Glass non-returnable | J13: 0.186 | K13: 0.43 | L13: kg CO2e | M13: Total GWP from Tables 8 and 10 | N13: Academic | O13: none | P13: yes | Q13: https://doi.org/10.1007/s11367-020-01804-x | R13: =K13/J13 -> 2.311828 | S13: =LN(R13) -> 0.83803853 | T13: Glass
A14: P13 | B14: S8 | C14: Stefanini et al. (milk bottles) | D14: 2021 | E14: Italy | F14: Milk | G14: 1 L | H14: PET bottle | I14: Returnable glass (8 uses) | J14: 0.186 | K14: 0.208 | L14: kg CO2e | M14: Fig. 9 (8 uses = 2.08E-01) | N14: Academic | O14: none | P14: yes | Q14: https://doi.org/10.1007/s11367-020-01804-x | R14: =K14/J14 -> 1.1182796 | S14: =LN(R14) -> 0.11179141 | T14: Reusable glass
A15: P14 | B15: S8 | C15: Stefanini et al. (milk bottles) | D15: 2021 | E15: Italy | F15: Milk | G15: 1 L | H15: PET bottle | I15: Returnable glass (30 uses) | J15: 0.186 | K15: 0.185 | L15: kg CO2e | M15: Fig. 9 (30 uses = 1.85E-01) | N15: Academic | O15: none | P15: yes | Q15: https://doi.org/10.1007/s11367-020-01804-x | R15: =K15/J15 -> 0.99462366 | S15: =LN(R15) -> -0.0053908486 | T15: Reusable glass
A16: P15 | B16: S8 | C16: Stefanini et al. (milk bottles) | D16: 2021 | E16: Italy | F16: Milk | G16: 1 L | H16: PET bottle (virgin) | I16: R-PET bottle (50% recycled) | J16: 0.186 | K16: 0.152 | L16: kg CO2e | M16: Tables 8 and 9 | N16: Academic | O16: none | P16: yes | Q16: https://doi.org/10.1007/s11367-020-01804-x | R16: =K16/J16 -> 0.8172043 | S16: =LN(R16) -> -0.20186615 | T16: Recycled PET
A17: P16 | B17: S9 | C17: Pasqualino et al. (as tabulated in Stefanini 2021 Table 1) | D17: 2011 | E17: Spain | F17: Beverages | G17: 1 L | H17: PET 1.5 L water | I17: Aseptic carton 1 L juice | J17: 0.078 | K17: 0.113 | L17: kg CO2e/L | M17: Secondary citation in open-access Table 1 (different beverages) | N17: Academic | O17: none | P17: yes | Q17: https://doi.org/10.1007/s11367-020-01804-x | R17: =K17/J17 -> 1.4487179 | S17: =LN(R17) -> 0.37067899 | T17: Carton | U17: Compares different beverages (PET water vs carton juice); second-hand
A18: P17 | B18: S9 | C18: Pasqualino et al. (as tabulated in Stefanini 2021 Table 1) | D18: 2011 | E18: Spain | F18: Beverages | G18: 1 L | H18: PET 1.5 L water | I18: Aluminium can 0.33 L beer | J18: 0.078 | K18: 0.826 | L18: kg CO2e/L | M18: Secondary citation in open-access Table 1 (different beverages) | N18: Academic | O18: none | P18: yes | Q18: https://doi.org/10.1007/s11367-020-01804-x | R18: =K18/J18 -> 10.589744 | S18: =LN(R18) -> 2.3598859 | T18: Aluminium | U18: Compares different beverages (PET water vs beer can); second-hand
A19: P18 | B19: S10 | C19: Amienyo et al. (carbonated soft drinks; as tabulated in Stefanini 2021) | D19: 2013 | E19: UK | F19: Carbonated drinks | G19: 1 L | H19: PET 0.5 L | I19: Glass 0.75 L | J19: 0.293 | K19: 0.555 | L19: kg CO2e/L | M19: Secondary citation in open-access Table 1 | N19: Academic | O19: none | P19: yes | Q19: https://doi.org/10.1007/s11367-020-01804-x | R19: =K19/J19 -> 1.894198 | S19: =LN(R19) -> 0.6387955 | T19: Glass | U19: Second-hand (Stefanini Table 1)
A20: P19 | B20: S10 | C20: Amienyo et al. (carbonated soft drinks; as tabulated in Stefanini 2021) | D20: 2013 | E20: UK | F20: Carbonated drinks | G20: 1 L | H20: PET 0.5 L | I20: Aluminium can 0.33 L | J20: 0.293 | K20: 0.312 | L20: kg CO2e/L | M20: Secondary citation in open-access Table 1 | N20: Academic | O20: none | P20: yes | Q20: https://doi.org/10.1007/s11367-020-01804-x | R20: =K20/J20 -> 1.0648464 | S20: =LN(R20) -> 0.062830579 | T20: Aluminium | U20: Second-hand
A21: P20 | B21: S10 | C21: Amienyo et al. (carbonated soft drinks; as tabulated in Stefanini 2021) | D21: 2013 | E21: UK | F21: Carbonated drinks | G21: 1 L | H21: PET 2 L | I21: Glass 0.75 L | J21: 0.151 | K21: 0.555 | L21: kg CO2e/L | M21: Secondary citation in open-access Table 1 | N21: Academic | O21: none | P21: yes | Q21: https://doi.org/10.1007/s11367-020-01804-x | R21: =K21/J21 -> 3.6754967 | S21: =LN(R21) -> 1.3016883 | T21: Glass | U21: Second-hand
A22: P21 | B22: S10 | C22: Amienyo et al. (carbonated soft drinks; as tabulated in Stefanini 2021) | D22: 2013 | E22: UK | F22: Carbonated drinks | G22: 1 L | H22: PET 2 L | I22: Aluminium can 0.33 L | J22: 0.151 | K22: 0.312 | L22: kg CO2e/L | M22: Secondary citation in open-access Table 1 | N22: Academic | O22: none | P22: yes | Q22: https://doi.org/10.1007/s11367-020-01804-x | R22: =K22/J22 -> 2.0662252 | S22: =LN(R22) -> 0.72572335 | T22: Aluminium | U22: Second-hand
A23: P22 | B23: S11 | C23: Saleh (Palestine; as tabulated in Stefanini 2021) | D23: 2015 | E23: Palestine | F23: Beverages | G23: 1000 L (units as tabulated) | H23: PET 2 L | I23: Glass 0.33 L | J23: 0.044 | K23: 2.57 | L23: as tabulated (kg CO2e per FU) | M23: Secondary citation in open-access Table 1; extreme ratio - flagged as possible unit issue | N23: Academic | O23: none | P23: yes | Q23: https://doi.org/10.1007/s11367-020-01804-x | R23: =K23/J23 -> 58.409091 | S23: =LN(R23) -> 4.0674715 | T23: Glass | U23: Extreme ratio - possible unit issue; second-hand
A24: P23 | B24: S11 | C24: Saleh (Palestine; as tabulated in Stefanini 2021) | D24: 2015 | E24: Palestine | F24: Beverages | G24: 1000 L (units as tabulated) | H24: PET 2 L | I24: Aluminium can 0.33 L | J24: 0.044 | K24: 0.46 | L24: as tabulated (kg CO2e per FU) | M24: Secondary citation in open-access Table 1; extreme ratio - flagged as possible unit issue | N24: Academic | O24: none | P24: yes | Q24: https://doi.org/10.1007/s11367-020-01804-x | R24: =K24/J24 -> 10.454545 | S24: =LN(R24) -> 2.3470369 | T24: Aluminium | U24: Extreme ratio - possible unit issue; second-hand
A25: P24 | B25: S12 | C25: Mata & Costa (beer bottles; as tabulated in Stefanini 2021) | D25: 2001 | E25: Portugal | F25: Beer | G25: 0.33 L bottle | H25: Glass non-returnable (cycle 1) | I25: Glass returnable (cycle 1) | J25: 0.12 | K25: 0.13 | L25: kg CO2e/L | M25: Secondary citation in open-access Table 1 | N25: Academic | O25: none | P25: no (glass reuse vs single-use) | Q25: https://doi.org/10.1007/s11367-020-01804-x | R25: =K25/J25 -> 1.0833333 | S25: =LN(R25) -> 0.080042708 | T25: Reuse vs single-use glass | U25: Second-hand; not pooled
A26: P25 | B26: S12 | C26: Mata & Costa (beer bottles; as tabulated in Stefanini 2021) | D26: 2001 | E26: Portugal | F26: Beer | G26: 0.33 L bottle | H26: Glass non-returnable (cycle 6) | I26: Glass returnable (cycle 6) | J26: 0.59 | K26: 0.28 | L26: kg CO2e/L | M26: Secondary citation in open-access Table 1 | N26: Academic | O26: none | P26: no (glass reuse vs single-use) | Q26: https://doi.org/10.1007/s11367-020-01804-x | R26: =K26/J26 -> 0.47457627 | S26: =LN(R26) -> -0.74533293 | T26: Reuse vs single-use glass | U26: Second-hand; not pooled
A27: P26 | B27: S13 | C27: Ferrara et al. (mineral water) | D27: 2021 | E27: Italy | F27: Natural water | G27: 1 L | H27: PET 1 L | I27: Reusable glass (7 uses) | J27: 188.6 | K27: 190.6 | L27: g CO2e | M27: Sum of stage values in Fig. 4a | N27: Academic | O27: none | P27: yes | Q27: https://doi.org/10.3390/recycling6030050 | R27: =K27/J27 -> 1.0106045 | S27: =LN(R27) -> 0.010548621 | T27: Reusable glass
A28: P27 | B28: S13 | C28: Ferrara et al. (mineral water) | D28: 2021 | E28: Italy | F28: Sparkling water | G28: 1 L | H28: PET 1 L | I28: Reusable glass (7 uses) | J28: 191.9 | K28: 166.1 | L28: g CO2e | M28: Sum of stage values in Fig. 4a | N28: Academic | O28: none | P28: yes | Q28: https://doi.org/10.3390/recycling6030050 | R28: =K28/J28 -> 0.86555498 | S28: =LN(R28) -> -0.14438439 | T28: Reusable glass

Sheet S2_Meta_analysis
A1: group | B1: k_studies | C1: n_pairs | D1: mean_ln | E1: ratio | F1: ci_low | G1: ci_high | H1: pct_pairs_alt_better | I1: between_study_SD_ln
A2: All plastic-baseline pairs | B2: 11 | C2: 23 | D2: 0.80100638 | E2: 2.2277818 | F2: 1.2572931 | G2: 4.186967 | H2: 30.434783 | I2: 1.0722739
A3: Glass vs plastic | B3: 6 | C3: 7 | D3: 1.6075301 | E3: 4.9904698 | F3: 2.3783057 | G3: 14.324535 | H3: 0 | I3: 1.2757337
A4: Reusable glass vs plastic | B4: 2 | C4: 4 | D4: -0.006858802 | E4: 0.99316467 | F4: 0.935272 | G4: 1.0546408 | H4: 50 | I4: 0.084936366
A5: Aluminium vs plastic | B5: 6 | C5: 7 | D5: 1.1658029 | E5: 3.2084978 | F5: 1.4037062 | G5: 7.0438485 | H5: 14.285714 | I5: 1.0921401
A6: Carton vs plastic | B6: 3 | C6: 4 | D6: -0.096121933 | E6: 0.90835325 | F6: 0.60255508 | G6: 1.4487179 | H6: 75 | I6: 0.44133363
A7: Academic-funded only | B7: 9 | C7: 20 | D7: 0.88561919 | E7: 2.4244851 | F7: 1.3154955 | G7: 4.973869 | H7: 25 | I7: 1.0854329
A8: All excl. Saleh (extreme ratios) | B8: 10 | C8: 21 | D8: 0.56038159 | E8: 1.7513407 | F8: 1.1311135 | G8: 2.731426 | H8: 33.333333 | I8: 0.7548864
A9: Industry-linked only | B9: 2 | C9: 3 | D9: 0.42024872 | E9: 1.5223402 | F9: 0.60255508 | G9: 3.8461538 | H9: 66.666667 | I9: 1.3107284
A11: LIVE FORMULA VERSION (recalculates from sheet 1). Bootstrap intervals in the table above come from analysis.py and cannot be written as worksheet formulas; the t-intervals below are the formula equivalent.
A12: group | B12: k_studies | C12: n_pairs | D12: mean_ln | E12: ratio | F12: t_ci_low | G12: t_ci_high | H12: pct_pairs_alt_better | I12: between_study_SD_ln
A13: All plastic-baseline pairs | B13: =COUNTIF(S2b_Study_means!$A$2:$A$50,A13) -> 11 | C13: =SUMIF(S2b_Study_means!$A$2:$A$50,A13,S2b_Study_means!$D$2:$D$50) -> 23 | D13: =AVERAGEIF(S2b_Study_means!$A$2:$A$50,A13,S2b_Study_means!$C$2:$C$50) -> 0.80100638 | E13: =EXP(D13) -> 2.2277818 | F13: =IF(B13>2,EXP(D13-TINV(0.05,B13-1)*I13/SQRT(B13)),"n/a") -> 1.0839838 | G13: =IF(B13>2,EXP(D13+TINV(0.05,B13-1)*I13/SQRT(B13)),"n/a") -> 4.5784924 | H13: =100*SUMIF(S2b_Study_means!$A$2:$A$50,A13,S2b_Study_means!$E$2:$E$50)/C13 -> 30.434783 | I13: =IF(B13>1,SQRT((SUMPRODUCT((S2b_Study_means!$A$2:$A$50=A13)*(S2b_Study_means!$C$2:$C$50^2))-B13*D13^2)/(B13-1)),"n/a") -> 1.0722739
A14: Glass vs plastic | B14: =COUNTIF(S2b_Study_means!$A$2:$A$50,A14) -> 6 | C14: =SUMIF(S2b_Study_means!$A$2:$A$50,A14,S2b_Study_means!$D$2:$D$50) -> 7 | D14: =AVERAGEIF(S2b_Study_means!$A$2:$A$50,A14,S2b_Study_means!$C$2:$C$50) -> 1.6075301 | E14: =EXP(D14) -> 4.9904698 | F14: =IF(B14>2,EXP(D14-TINV(0.05,B14-1)*I14/SQRT(B14)),"n/a") -> 1.3083013 | G14: =IF(B14>2,EXP(D14+TINV(0.05,B14-1)*I14/SQRT(B14)),"n/a") -> 19.035973 | H14: =100*SUMIF(S2b_Study_means!$A$2:$A$50,A14,S2b_Study_means!$E$2:$E$50)/C14 -> 0 | I14: =IF(B14>1,SQRT((SUMPRODUCT((S2b_Study_means!$A$2:$A$50=A14)*(S2b_Study_means!$C$2:$C$50^2))-B14*D14^2)/(B14-1)),"n/a") -> 1.2757337
A15: Reusable glass vs plastic | B15: =COUNTIF(S2b_Study_means!$A$2:$A$50,A15) -> 2 | C15: =SUMIF(S2b_Study_means!$A$2:$A$50,A15,S2b_Study_means!$D$2:$D$50) -> 4 | D15: =AVERAGEIF(S2b_Study_means!$A$2:$A$50,A15,S2b_Study_means!$C$2:$C$50) -> -0.006858802 | E15: =EXP(D15) -> 0.99316467 | F15: =IF(B15>2,EXP(D15-TINV(0.05,B15-1)*I15/SQRT(B15)),"n/a") -> n/a | G15: =IF(B15>2,EXP(D15+TINV(0.05,B15-1)*I15/SQRT(B15)),"n/a") -> n/a | H15: =100*SUMIF(S2b_Study_means!$A$2:$A$50,A15,S2b_Study_means!$E$2:$E$50)/C15 -> 50 | I15: =IF(B15>1,SQRT((SUMPRODUCT((S2b_Study_means!$A$2:$A$50=A15)*(S2b_Study_means!$C$2:$C$50^2))-B15*D15^2)/(B15-1)),"n/a") -> 0.084936366
A16: Aluminium vs plastic | B16: =COUNTIF(S2b_Study_means!$A$2:$A$50,A16) -> 6 | C16: =SUMIF(S2b_Study_means!$A$2:$A$50,A16,S2b_Study_means!$D$2:$D$50) -> 7 | D16: =AVERAGEIF(S2b_Study_means!$A$2:$A$50,A16,S2b_Study_means!$C$2:$C$50) -> 1.1658029 | E16: =EXP(D16) -> 3.2084978 | F16: =IF(B16>2,EXP(D16-TINV(0.05,B16-1)*I16/SQRT(B16)),"n/a") -> 1.0198668 | G16: =IF(B16>2,EXP(D16+TINV(0.05,B16-1)*I16/SQRT(B16)),"n/a") -> 10.093924 | H16: =100*SUMIF(S2b_Study_means!$A$2:$A$50,A16,S2b_Study_means!$E$2:$E$50)/C16 -> 14.285714 | I16: =IF(B16>1,SQRT((SUMPRODUCT((S2b_Study_means!$A$2:$A$50=A16)*(S2b_Study_means!$C$2:$C$50^2))-B16*D16^2)/(B16-1)),"n/a") -> 1.0921401
A17: Carton vs plastic | B17: =COUNTIF(S2b_Study_means!$A$2:$A$50,A17) -> 3 | C17: =SUMIF(S2b_Study_means!$A$2:$A$50,A17,S2b_Study_means!$D$2:$D$50) -> 4 | D17: =AVERAGEIF(S2b_Study_means!$A$2:$A$50,A17,S2b_Study_means!$C$2:$C$50) -> -0.096121933 | E17: =EXP(D17) -> 0.90835325 | F17: =IF(B17>2,EXP(D17-TINV(0.05,B17-1)*I17/SQRT(B17)),"n/a") -> 0.30347518 | G17: =IF(B17>2,EXP(D17+TINV(0.05,B17-1)*I17/SQRT(B17)),"n/a") -> 2.7188571 | H17: =100*SUMIF(S2b_Study_means!$A$2:$A$50,A17,S2b_Study_means!$E$2:$E$50)/C17 -> 75 | I17: =IF(B17>1,SQRT((SUMPRODUCT((S2b_Study_means!$A$2:$A$50=A17)*(S2b_Study_means!$C$2:$C$50^2))-B17*D17^2)/(B17-1)),"n/a") -> 0.44133363
A18: Academic-funded only | B18: =COUNTIF(S2b_Study_means!$A$2:$A$50,A18) -> 9 | C18: =SUMIF(S2b_Study_means!$A$2:$A$50,A18,S2b_Study_means!$D$2:$D$50) -> 20 | D18: =AVERAGEIF(S2b_Study_means!$A$2:$A$50,A18,S2b_Study_means!$C$2:$C$50) -> 0.88561919 | E18: =EXP(D18) -> 2.4244851 | F18: =IF(B18>2,EXP(D18-TINV(0.05,B18-1)*I18/SQRT(B18)),"n/a") -> 1.0526192 | G18: =IF(B18>2,EXP(D18+TINV(0.05,B18-1)*I18/SQRT(B18)),"n/a") -> 5.5842872 | H18: =100*SUMIF(S2b_Study_means!$A$2:$A$50,A18,S2b_Study_means!$E$2:$E$50)/C18 -> 25 | I18: =IF(B18>1,SQRT((SUMPRODUCT((S2b_Study_means!$A$2:$A$50=A18)*(S2b_Study_means!$C$2:$C$50^2))-B18*D18^2)/(B18-1)),"n/a") -> 1.0854329
A19: All excl. Saleh (extreme ratios) | B19: =COUNTIF(S2b_Study_means!$A$2:$A$50,A19) -> 10 | C19: =SUMIF(S2b_Study_means!$A$2:$A$50,A19,S2b_Study_means!$D$2:$D$50) -> 21 | D19: =AVERAGEIF(S2b_Study_means!$A$2:$A$50,A19,S2b_Study_means!$C$2:$C$50) -> 0.56038159 | E19: =EXP(D19) -> 1.7513407 | F19: =IF(B19>2,EXP(D19-TINV(0.05,B19-1)*I19/SQRT(B19)),"n/a") -> 1.0205772 | G19: =IF(B19>2,EXP(D19+TINV(0.05,B19-1)*I19/SQRT(B19)),"n/a") -> 3.0053523 | H19: =100*SUMIF(S2b_Study_means!$A$2:$A$50,A19,S2b_Study_means!$E$2:$E$50)/C19 -> 33.333333 | I19: =IF(B19>1,SQRT((SUMPRODUCT((S2b_Study_means!$A$2:$A$50=A19)*(S2b_Study_means!$C$2:$C$50^2))-B19*D19^2)/(B19-1)),"n/a") -> 0.7548864
A20: Industry-linked only | B20: =COUNTIF(S2b_Study_means!$A$2:$A$50,A20) -> 2 | C20: =SUMIF(S2b_Study_means!$A$2:$A$50,A20,S2b_Study_means!$D$2:$D$50) -> 3 | D20: =AVERAGEIF(S2b_Study_means!$A$2:$A$50,A20,S2b_Study_means!$C$2:$C$50) -> 0.42024872 | E20: =EXP(D20) -> 1.5223402 | F20: =IF(B20>2,EXP(D20-TINV(0.05,B20-1)*I20/SQRT(B20)),"n/a") -> n/a | G20: =IF(B20>2,EXP(D20+TINV(0.05,B20-1)*I20/SQRT(B20)),"n/a") -> n/a | H20: =100*SUMIF(S2b_Study_means!$A$2:$A$50,A20,S2b_Study_means!$E$2:$E$50)/C20 -> 66.666667 | I20: =IF(B20>1,SQRT((SUMPRODUCT((S2b_Study_means!$A$2:$A$50=A20)*(S2b_Study_means!$C$2:$C$50^2))-B20*D20^2)/(B20-1)),"n/a") -> 1.3107284

Sheet S2b_Study_means
A1: group | B1: study_id | C1: study_mean_ln_ratio | D1: n_pairs | E1: n_pairs_alt_better
A2: All plastic-baseline pairs | B2: S1 | C2: =AVERAGEIFS(S1_Extracted_pairs!$S$2:$S$28,S1_Extracted_pairs!$B$2:$B$28,$B2,S1_Extracted_pairs!$P$2:$P$28,"yes") -> 0.78322613 | D2: =COUNTIFS(S1_Extracted_pairs!$B$2:$B$28,$B2,S1_Extracted_pairs!$P$2:$P$28,"yes") -> 3 | E2: =COUNTIFS(S1_Extracted_pairs!$B$2:$B$28,$B2,S1_Extracted_pairs!$P$2:$P$28,"yes",S1_Extracted_pairs!$R$2:$R$28,"<1") -> 1
A3: All plastic-baseline pairs | B3: S2 | C3: =AVERAGEIFS(S1_Extracted_pairs!$S$2:$S$28,S1_Extracted_pairs!$B$2:$B$28,$B3,S1_Extracted_pairs!$P$2:$P$28,"yes") -> 0.56703818 | D3: =COUNTIFS(S1_Extracted_pairs!$B$2:$B$28,$B3,S1_Extracted_pairs!$P$2:$P$28,"yes") -> 1 | E3: =COUNTIFS(S1_Extracted_pairs!$B$2:$B$28,$B3,S1_Extracted_pairs!$P$2:$P$28,"yes",S1_Extracted_pairs!$R$2:$R$28,"<1") -> 0
A4: All plastic-baseline pairs | B4: S3 | C4: =AVERAGEIFS(S1_Extracted_pairs!$S$2:$S$28,S1_Extracted_pairs!$B$2:$B$28,$B4,S1_Extracted_pairs!$P$2:$P$28,"yes") -> 1.3470736 | D4: =COUNTIFS(S1_Extracted_pairs!$B$2:$B$28,$B4,S1_Extracted_pairs!$P$2:$P$28,"yes") -> 1 | E4: =COUNTIFS(S1_Extracted_pairs!$B$2:$B$28,$B4,S1_Extracted_pairs!$P$2:$P$28,"yes",S1_Extracted_pairs!$R$2:$R$28,"<1") -> 0
A5: All plastic-baseline pairs | B5: S4 | C5: =AVERAGEIFS(S1_Extracted_pairs!$S$2:$S$28,S1_Extracted_pairs!$B$2:$B$28,$B5,S1_Extracted_pairs!$P$2:$P$28,"yes") -> 1.652252 | D5: =COUNTIFS(S1_Extracted_pairs!$B$2:$B$28,$B5,S1_Extracted_pairs!$P$2:$P$28,"yes") -> 1 | E5: =COUNTIFS(S1_Extracted_pairs!$B$2:$B$28,$B5,S1_Extracted_pairs!$P$2:$P$28,"yes",S1_Extracted_pairs!$R$2:$R$28,"<1") -> 0
A6: All plastic-baseline pairs | B6: S5 | C6: =AVERAGEIFS(S1_Extracted_pairs!$S$2:$S$28,S1_Extracted_pairs!$B$2:$B$28,$B6,S1_Extracted_pairs!$P$2:$P$28,"yes") -> -0.5065762 | D6: =COUNTIFS(S1_Extracted_pairs!$B$2:$B$28,$B6,S1_Extracted_pairs!$P$2:$P$28,"yes") -> 2 | E6: =COUNTIFS(S1_Extracted_pairs!$B$2:$B$28,$B6,S1_Extracted_pairs!$P$2:$P$28,"yes",S1_Extracted_pairs!$R$2:$R$28,"<1") -> 2
A7: All plastic-baseline pairs | B7: S6 | C7: =AVERAGEIFS(S1_Extracted_pairs!$S$2:$S$28,S1_Extracted_pairs!$B$2:$B$28,$B7,S1_Extracted_pairs!$P$2:$P$28,"yes") -> -0.40546511 | D7: =COUNTIFS(S1_Extracted_pairs!$B$2:$B$28,$B7,S1_Extracted_pairs!$P$2:$P$28,"yes") -> 1 | E7: =COUNTIFS(S1_Extracted_pairs!$B$2:$B$28,$B7,S1_Extracted_pairs!$P$2:$P$28,"yes",S1_Extracted_pairs!$R$2:$R$28,"<1") -> 1
A8: All plastic-baseline pairs | B8: S8 | C8: =AVERAGEIFS(S1_Extracted_pairs!$S$2:$S$28,S1_Extracted_pairs!$B$2:$B$28,$B8,S1_Extracted_pairs!$P$2:$P$28,"yes") -> 0.18564323 | D8: =COUNTIFS(S1_Extracted_pairs!$B$2:$B$28,$B8,S1_Extracted_pairs!$P$2:$P$28,"yes") -> 4 | E8: =COUNTIFS(S1_Extracted_pairs!$B$2:$B$28,$B8,S1_Extracted_pairs!$P$2:$P$28,"yes",S1_Extracted_pairs!$R$2:$R$28,"<1") -> 2
A9: All plastic-baseline pairs | B9: S9 | C9: =AVERAGEIFS(S1_Extracted_pairs!$S$2:$S$28,S1_Extracted_pairs!$B$2:$B$28,$B9,S1_Extracted_pairs!$P$2:$P$28,"yes") -> 1.3652825 | D9: =COUNTIFS(S1_Extracted_pairs!$B$2:$B$28,$B9,S1_Extracted_pairs!$P$2:$P$28,"yes") -> 2 | E9: =COUNTIFS(S1_Extracted_pairs!$B$2:$B$28,$B9,S1_Extracted_pairs!$P$2:$P$28,"yes",S1_Extracted_pairs!$R$2:$R$28,"<1") -> 0
A10: All plastic-baseline pairs | B10: S10 | C10: =AVERAGEIFS(S1_Extracted_pairs!$S$2:$S$28,S1_Extracted_pairs!$B$2:$B$28,$B10,S1_Extracted_pairs!$P$2:$P$28,"yes") -> 0.68225943 | D10: =COUNTIFS(S1_Extracted_pairs!$B$2:$B$28,$B10,S1_Extracted_pairs!$P$2:$P$28,"yes") -> 4 | E10: =COUNTIFS(S1_Extracted_pairs!$B$2:$B$28,$B10,S1_Extracted_pairs!$P$2:$P$28,"yes",S1_Extracted_pairs!$R$2:$R$28,"<1") -> 0
A11: All plastic-baseline pairs | B11: S11 | C11: =AVERAGEIFS(S1_Extracted_pairs!$S$2:$S$28,S1_Extracted_pairs!$B$2:$B$28,$B11,S1_Extracted_pairs!$P$2:$P$28,"yes") -> 3.2072542 | D11: =COUNTIFS(S1_Extracted_pairs!$B$2:$B$28,$B11,S1_Extracted_pairs!$P$2:$P$28,"yes") -> 2 | E11: =COUNTIFS(S1_Extracted_pairs!$B$2:$B$28,$B11,S1_Extracted_pairs!$P$2:$P$28,"yes",S1_Extracted_pairs!$R$2:$R$28,"<1") -> 0
A12: All plastic-baseline pairs | B12: S13 | C12: =AVERAGEIFS(S1_Extracted_pairs!$S$2:$S$28,S1_Extracted_pairs!$B$2:$B$28,$B12,S1_Extracted_pairs!$P$2:$P$28,"yes") -> -0.066917883 | D12: =COUNTIFS(S1_Extracted_pairs!$B$2:$B$28,$B12,S1_Extracted_pairs!$P$2:$P$28,"yes") -> 2 | E12: =COUNTIFS(S1_Extracted_pairs!$B$2:$B$28,$B12,S1_Extracted_pairs!$P$2:$P$28,"yes",S1_Extracted_pairs!$R$2:$R$28,"<1") -> 1
A13: Glass vs plastic | B13: S1 | C13: =AVERAGEIFS(S1_Extracted_pairs!$S$2:$S$28,S1_Extracted_pairs!$B$2:$B$28,$B13,S1_Extracted_pairs!$P$2:$P$28,"yes",S1_Extracted_pairs!$T$2:$T$28,"Glass") -> 1.5501382 | D13: =COUNTIFS(S1_Extracted_pairs!$B$2:$B$28,$B13,S1_Extracted_pairs!$P$2:$P$28,"yes",S1_Extracted_pairs!$T$2:$T$28,"Glass") -> 1 | E13: =COUNTIFS(S1_Extracted_pairs!$B$2:$B$28,$B13,S1_Extracted_pairs!$P$2:$P$28,"yes",S1_Extracted_pairs!$T$2:$T$28,"Glass",S1_Extracted_pairs!$R$2:$R$28,"<1") -> 0
A14: Glass vs plastic | B14: S2 | C14: =AVERAGEIFS(S1_Extracted_pairs!$S$2:$S$28,S1_Extracted_pairs!$B$2:$B$28,$B14,S1_Extracted_pairs!$P$2:$P$28,"yes",S1_Extracted_pairs!$T$2:$T$28,"Glass") -> 0.56703818 | D14: =COUNTIFS(S1_Extracted_pairs!$B$2:$B$28,$B14,S1_Extracted_pairs!$P$2:$P$28,"yes",S1_Extracted_pairs!$T$2:$T$28,"Glass") -> 1 | E14: =COUNTIFS(S1_Extracted_pairs!$B$2:$B$28,$B14,S1_Extracted_pairs!$P$2:$P$28,"yes",S1_Extracted_pairs!$T$2:$T$28,"Glass",S1_Extracted_pairs!$R$2:$R$28,"<1") -> 0
A15: Glass vs plastic | B15: S4 | C15: =AVERAGEIFS(S1_Extracted_pairs!$S$2:$S$28,S1_Extracted_pairs!$B$2:$B$28,$B15,S1_Extracted_pairs!$P$2:$P$28,"yes",S1_Extracted_pairs!$T$2:$T$28,"Glass") -> 1.652252 | D15: =COUNTIFS(S1_Extracted_pairs!$B$2:$B$28,$B15,S1_Extracted_pairs!$P$2:$P$28,"yes",S1_Extracted_pairs!$T$2:$T$28,"Glass") -> 1 | E15: =COUNTIFS(S1_Extracted_pairs!$B$2:$B$28,$B15,S1_Extracted_pairs!$P$2:$P$28,"yes",S1_Extracted_pairs!$T$2:$T$28,"Glass",S1_Extracted_pairs!$R$2:$R$28,"<1") -> 0
A16: Glass vs plastic | B16: S8 | C16: =AVERAGEIFS(S1_Extracted_pairs!$S$2:$S$28,S1_Extracted_pairs!$B$2:$B$28,$B16,S1_Extracted_pairs!$P$2:$P$28,"yes",S1_Extracted_pairs!$T$2:$T$28,"Glass") -> 0.83803853 | D16: =COUNTIFS(S1_Extracted_pairs!$B$2:$B$28,$B16,S1_Extracted_pairs!$P$2:$P$28,"yes",S1_Extracted_pairs!$T$2:$T$28,"Glass") -> 1 | E16: =COUNTIFS(S1_Extracted_pairs!$B$2:$B$28,$B16,S1_Extracted_pairs!$P$2:$P$28,"yes",S1_Extracted_pairs!$T$2:$T$28,"Glass",S1_Extracted_pairs!$R$2:$R$28,"<1") -> 0
A17: Glass vs plastic | B17: S10 | C17: =AVERAGEIFS(S1_Extracted_pairs!$S$2:$S$28,S1_Extracted_pairs!$B$2:$B$28,$B17,S1_Extracted_pairs!$P$2:$P$28,"yes",S1_Extracted_pairs!$T$2:$T$28,"Glass") -> 0.97024189 | D17: =COUNTIFS(S1_Extracted_pairs!$B$2:$B$28,$B17,S1_Extracted_pairs!$P$2:$P$28,"yes",S1_Extracted_pairs!$T$2:$T$28,"Glass") -> 2 | E17: =COUNTIFS(S1_Extracted_pairs!$B$2:$B$28,$B17,S1_Extracted_pairs!$P$2:$P$28,"yes",S1_Extracted_pairs!$T$2:$T$28,"Glass",S1_Extracted_pairs!$R$2:$R$28,"<1") -> 0
A18: Glass vs plastic | B18: S11 | C18: =AVERAGEIFS(S1_Extracted_pairs!$S$2:$S$28,S1_Extracted_pairs!$B$2:$B$28,$B18,S1_Extracted_pairs!$P$2:$P$28,"yes",S1_Extracted_pairs!$T$2:$T$28,"Glass") -> 4.0674715 | D18: =COUNTIFS(S1_Extracted_pairs!$B$2:$B$28,$B18,S1_Extracted_pairs!$P$2:$P$28,"yes",S1_Extracted_pairs!$T$2:$T$28,"Glass") -> 1 | E18: =COUNTIFS(S1_Extracted_pairs!$B$2:$B$28,$B18,S1_Extracted_pairs!$P$2:$P$28,"yes",S1_Extracted_pairs!$T$2:$T$28,"Glass",S1_Extracted_pairs!$R$2:$R$28,"<1") -> 0
A19: Reusable glass vs plastic | B19: S8 | C19: =AVERAGEIFS(S1_Extracted_pairs!$S$2:$S$28,S1_Extracted_pairs!$B$2:$B$28,$B19,S1_Extracted_pairs!$P$2:$P$28,"yes",S1_Extracted_pairs!$T$2:$T$28,"Reusable glass") -> 0.053200279 | D19: =COUNTIFS(S1_Extracted_pairs!$B$2:$B$28,$B19,S1_Extracted_pairs!$P$2:$P$28,"yes",S1_Extracted_pairs!$T$2:$T$28,"Reusable glass") -> 2 | E19: =COUNTIFS(S1_Extracted_pairs!$B$2:$B$28,$B19,S1_Extracted_pairs!$P$2:$P$28,"yes",S1_Extracted_pairs!$T$2:$T$28,"Reusable glass",S1_Extracted_pairs!$R$2:$R$28,"<1") -> 1
A20: Reusable glass vs plastic | B20: S13 | C20: =AVERAGEIFS(S1_Extracted_pairs!$S$2:$S$28,S1_Extracted_pairs!$B$2:$B$28,$B20,S1_Extracted_pairs!$P$2:$P$28,"yes",S1_Extracted_pairs!$T$2:$T$28,"Reusable glass") -> -0.066917883 | D20: =COUNTIFS(S1_Extracted_pairs!$B$2:$B$28,$B20,S1_Extracted_pairs!$P$2:$P$28,"yes",S1_Extracted_pairs!$T$2:$T$28,"Reusable glass") -> 2 | E20: =COUNTIFS(S1_Extracted_pairs!$B$2:$B$28,$B20,S1_Extracted_pairs!$P$2:$P$28,"yes",S1_Extracted_pairs!$T$2:$T$28,"Reusable glass",S1_Extracted_pairs!$R$2:$R$28,"<1") -> 1
A21: Aluminium vs plastic | B21: S1 | C21: =AVERAGEIFS(S1_Extracted_pairs!$S$2:$S$28,S1_Extracted_pairs!$B$2:$B$28,$B21,S1_Extracted_pairs!$P$2:$P$28,"yes",S1_Extracted_pairs!$T$2:$T$28,"Aluminium") -> 0.95200881 | D21: =COUNTIFS(S1_Extracted_pairs!$B$2:$B$28,$B21,S1_Extracted_pairs!$P$2:$P$28,"yes",S1_Extracted_pairs!$T$2:$T$28,"Aluminium") -> 1 | E21: =COUNTIFS(S1_Extracted_pairs!$B$2:$B$28,$B21,S1_Extracted_pairs!$P$2:$P$28,"yes",S1_Extracted_pairs!$T$2:$T$28,"Aluminium",S1_Extracted_pairs!$R$2:$R$28,"<1") -> 0
A22: Aluminium vs plastic | B22: S3 | C22: =AVERAGEIFS(S1_Extracted_pairs!$S$2:$S$28,S1_Extracted_pairs!$B$2:$B$28,$B22,S1_Extracted_pairs!$P$2:$P$28,"yes",S1_Extracted_pairs!$T$2:$T$28,"Aluminium") -> 1.3470736 | D22: =COUNTIFS(S1_Extracted_pairs!$B$2:$B$28,$B22,S1_Extracted_pairs!$P$2:$P$28,"yes",S1_Extracted_pairs!$T$2:$T$28,"Aluminium") -> 1 | E22: =COUNTIFS(S1_Extracted_pairs!$B$2:$B$28,$B22,S1_Extracted_pairs!$P$2:$P$28,"yes",S1_Extracted_pairs!$T$2:$T$28,"Aluminium",S1_Extracted_pairs!$R$2:$R$28,"<1") -> 0
A23: Aluminium vs plastic | B23: S6 | C23: =AVERAGEIFS(S1_Extracted_pairs!$S$2:$S$28,S1_Extracted_pairs!$B$2:$B$28,$B23,S1_Extracted_pairs!$P$2:$P$28,"yes",S1_Extracted_pairs!$T$2:$T$28,"Aluminium") -> -0.40546511 | D23: =COUNTIFS(S1_Extracted_pairs!$B$2:$B$28,$B23,S1_Extracted_pairs!$P$2:$P$28,"yes",S1_Extracted_pairs!$T$2:$T$28,"Aluminium") -> 1 | E23: =COUNTIFS(S1_Extracted_pairs!$B$2:$B$28,$B23,S1_Extracted_pairs!$P$2:$P$28,"yes",S1_Extracted_pairs!$T$2:$T$28,"Aluminium",S1_Extracted_pairs!$R$2:$R$28,"<1") -> 1
A24: Aluminium vs plastic | B24: S9 | C24: =AVERAGEIFS(S1_Extracted_pairs!$S$2:$S$28,S1_Extracted_pairs!$B$2:$B$28,$B24,S1_Extracted_pairs!$P$2:$P$28,"yes",S1_Extracted_pairs!$T$2:$T$28,"Aluminium") -> 2.3598859 | D24: =COUNTIFS(S1_Extracted_pairs!$B$2:$B$28,$B24,S1_Extracted_pairs!$P$2:$P$28,"yes",S1_Extracted_pairs!$T$2:$T$28,"Aluminium") -> 1 | E24: =COUNTIFS(S1_Extracted_pairs!$B$2:$B$28,$B24,S1_Extracted_pairs!$P$2:$P$28,"yes",S1_Extracted_pairs!$T$2:$T$28,"Aluminium",S1_Extracted_pairs!$R$2:$R$28,"<1") -> 0
A25: Aluminium vs plastic | B25: S10 | C25: =AVERAGEIFS(S1_Extracted_pairs!$S$2:$S$28,S1_Extracted_pairs!$B$2:$B$28,$B25,S1_Extracted_pairs!$P$2:$P$28,"yes",S1_Extracted_pairs!$T$2:$T$28,"Aluminium") -> 0.39427696 | D25: =COUNTIFS(S1_Extracted_pairs!$B$2:$B$28,$B25,S1_Extracted_pairs!$P$2:$P$28,"yes",S1_Extracted_pairs!$T$2:$T$28,"Aluminium") -> 2 | E25: =COUNTIFS(S1_Extracted_pairs!$B$2:$B$28,$B25,S1_Extracted_pairs!$P$2:$P$28,"yes",S1_Extracted_pairs!$T$2:$T$28,"Aluminium",S1_Extracted_pairs!$R$2:$R$28,"<1") -> 0
A26: Aluminium vs plastic | B26: S11 | C26: =AVERAGEIFS(S1_Extracted_pairs!$S$2:$S$28,S1_Extracted_pairs!$B$2:$B$28,$B26,S1_Extracted_pairs!$P$2:$P$28,"yes",S1_Extracted_pairs!$T$2:$T$28,"Aluminium") -> 2.3470369 | D26: =COUNTIFS(S1_Extracted_pairs!$B$2:$B$28,$B26,S1_Extracted_pairs!$P$2:$P$28,"yes",S1_Extracted_pairs!$T$2:$T$28,"Aluminium") -> 1 | E26: =COUNTIFS(S1_Extracted_pairs!$B$2:$B$28,$B26,S1_Extracted_pairs!$P$2:$P$28,"yes",S1_Extracted_pairs!$T$2:$T$28,"Aluminium",S1_Extracted_pairs!$R$2:$R$28,"<1") -> 0
A27: Carton vs plastic | B27: S1 | C27: =AVERAGEIFS(S1_Extracted_pairs!$S$2:$S$28,S1_Extracted_pairs!$B$2:$B$28,$B27,S1_Extracted_pairs!$P$2:$P$28,"yes",S1_Extracted_pairs!$T$2:$T$28,"Carton") -> -0.15246859 | D27: =COUNTIFS(S1_Extracted_pairs!$B$2:$B$28,$B27,S1_Extracted_pairs!$P$2:$P$28,"yes",S1_Extracted_pairs!$T$2:$T$28,"Carton") -> 1 | E27: =COUNTIFS(S1_Extracted_pairs!$B$2:$B$28,$B27,S1_Extracted_pairs!$P$2:$P$28,"yes",S1_Extracted_pairs!$T$2:$T$28,"Carton",S1_Extracted_pairs!$R$2:$R$28,"<1") -> 1
A28: Carton vs plastic | B28: S5 | C28: =AVERAGEIFS(S1_Extracted_pairs!$S$2:$S$28,S1_Extracted_pairs!$B$2:$B$28,$B28,S1_Extracted_pairs!$P$2:$P$28,"yes",S1_Extracted_pairs!$T$2:$T$28,"Carton") -> -0.5065762 | D28: =COUNTIFS(S1_Extracted_pairs!$B$2:$B$28,$B28,S1_Extracted_pairs!$P$2:$P$28,"yes",S1_Extracted_pairs!$T$2:$T$28,"Carton") -> 2 | E28: =COUNTIFS(S1_Extracted_pairs!$B$2:$B$28,$B28,S1_Extracted_pairs!$P$2:$P$28,"yes",S1_Extracted_pairs!$T$2:$T$28,"Carton",S1_Extracted_pairs!$R$2:$R$28,"<1") -> 2
A29: Carton vs plastic | B29: S9 | C29: =AVERAGEIFS(S1_Extracted_pairs!$S$2:$S$28,S1_Extracted_pairs!$B$2:$B$28,$B29,S1_Extracted_pairs!$P$2:$P$28,"yes",S1_Extracted_pairs!$T$2:$T$28,"Carton") -> 0.37067899 | D29: =COUNTIFS(S1_Extracted_pairs!$B$2:$B$28,$B29,S1_Extracted_pairs!$P$2:$P$28,"yes",S1_Extracted_pairs!$T$2:$T$28,"Carton") -> 1 | E29: =COUNTIFS(S1_Extracted_pairs!$B$2:$B$28,$B29,S1_Extracted_pairs!$P$2:$P$28,"yes",S1_Extracted_pairs!$T$2:$T$28,"Carton",S1_Extracted_pairs!$R$2:$R$28,"<1") -> 0
A30: Academic-funded only | B30: S1 | C30: =AVERAGEIFS(S1_Extracted_pairs!$S$2:$S$28,S1_Extracted_pairs!$B$2:$B$28,$B30,S1_Extracted_pairs!$P$2:$P$28,"yes",S1_Extracted_pairs!$N$2:$N$28,"Academic*") -> 0.78322613 | D30: =COUNTIFS(S1_Extracted_pairs!$B$2:$B$28,$B30,S1_Extracted_pairs!$P$2:$P$28,"yes",S1_Extracted_pairs!$N$2:$N$28,"Academic*") -> 3 | E30: =COUNTIFS(S1_Extracted_pairs!$B$2:$B$28,$B30,S1_Extracted_pairs!$P$2:$P$28,"yes",S1_Extracted_pairs!$N$2:$N$28,"Academic*",S1_Extracted_pairs!$R$2:$R$28,"<1") -> 1
A31: Academic-funded only | B31: S2 | C31: =AVERAGEIFS(S1_Extracted_pairs!$S$2:$S$28,S1_Extracted_pairs!$B$2:$B$28,$B31,S1_Extracted_pairs!$P$2:$P$28,"yes",S1_Extracted_pairs!$N$2:$N$28,"Academic*") -> 0.56703818 | D31: =COUNTIFS(S1_Extracted_pairs!$B$2:$B$28,$B31,S1_Extracted_pairs!$P$2:$P$28,"yes",S1_Extracted_pairs!$N$2:$N$28,"Academic*") -> 1 | E31: =COUNTIFS(S1_Extracted_pairs!$B$2:$B$28,$B31,S1_Extracted_pairs!$P$2:$P$28,"yes",S1_Extracted_pairs!$N$2:$N$28,"Academic*",S1_Extracted_pairs!$R$2:$R$28,"<1") -> 0
A32: Academic-funded only | B32: S4 | C32: =AVERAGEIFS(S1_Extracted_pairs!$S$2:$S$28,S1_Extracted_pairs!$B$2:$B$28,$B32,S1_Extracted_pairs!$P$2:$P$28,"yes",S1_Extracted_pairs!$N$2:$N$28,"Academic*") -> 1.652252 | D32: =COUNTIFS(S1_Extracted_pairs!$B$2:$B$28,$B32,S1_Extracted_pairs!$P$2:$P$28,"yes",S1_Extracted_pairs!$N$2:$N$28,"Academic*") -> 1 | E32: =COUNTIFS(S1_Extracted_pairs!$B$2:$B$28,$B32,S1_Extracted_pairs!$P$2:$P$28,"yes",S1_Extracted_pairs!$N$2:$N$28,"Academic*",S1_Extracted_pairs!$R$2:$R$28,"<1") -> 0
A33: Academic-funded only | B33: S6 | C33: =AVERAGEIFS(S1_Extracted_pairs!$S$2:$S$28,S1_Extracted_pairs!$B$2:$B$28,$B33,S1_Extracted_pairs!$P$2:$P$28,"yes",S1_Extracted_pairs!$N$2:$N$28,"Academic*") -> -0.40546511 | D33: =COUNTIFS(S1_Extracted_pairs!$B$2:$B$28,$B33,S1_Extracted_pairs!$P$2:$P$28,"yes",S1_Extracted_pairs!$N$2:$N$28,"Academic*") -> 1 | E33: =COUNTIFS(S1_Extracted_pairs!$B$2:$B$28,$B33,S1_Extracted_pairs!$P$2:$P$28,"yes",S1_Extracted_pairs!$N$2:$N$28,"Academic*",S1_Extracted_pairs!$R$2:$R$28,"<1") -> 1
A34: Academic-funded only | B34: S8 | C34: =AVERAGEIFS(S1_Extracted_pairs!$S$2:$S$28,S1_Extracted_pairs!$B$2:$B$28,$B34,S1_Extracted_pairs!$P$2:$P$28,"yes",S1_Extracted_pairs!$N$2:$N$28,"Academic*") -> 0.18564323 | D34: =COUNTIFS(S1_Extracted_pairs!$B$2:$B$28,$B34,S1_Extracted_pairs!$P$2:$P$28,"yes",S1_Extracted_pairs!$N$2:$N$28,"Academic*") -> 4 | E34: =COUNTIFS(S1_Extracted_pairs!$B$2:$B$28,$B34,S1_Extracted_pairs!$P$2:$P$28,"yes",S1_Extracted_pairs!$N$2:$N$28,"Academic*",S1_Extracted_pairs!$R$2:$R$28,"<1") -> 2
A35: Academic-funded only | B35: S9 | C35: =AVERAGEIFS(S1_Extracted_pairs!$S$2:$S$28,S1_Extracted_pairs!$B$2:$B$28,$B35,S1_Extracted_pairs!$P$2:$P$28,"yes",S1_Extracted_pairs!$N$2:$N$28,"Academic*") -> 1.3652825 | D35: =COUNTIFS(S1_Extracted_pairs!$B$2:$B$28,$B35,S1_Extracted_pairs!$P$2:$P$28,"yes",S1_Extracted_pairs!$N$2:$N$28,"Academic*") -> 2 | E35: =COUNTIFS(S1_Extracted_pairs!$B$2:$B$28,$B35,S1_Extracted_pairs!$P$2:$P$28,"yes",S1_Extracted_pairs!$N$2:$N$28,"Academic*",S1_Extracted_pairs!$R$2:$R$28,"<1") -> 0
A36: Academic-funded only | B36: S10 | C36: =AVERAGEIFS(S1_Extracted_pairs!$S$2:$S$28,S1_Extracted_pairs!$B$2:$B$28,$B36,S1_Extracted_pairs!$P$2:$P$28,"yes",S1_Extracted_pairs!$N$2:$N$28,"Academic*") -> 0.68225943 | D36: =COUNTIFS(S1_Extracted_pairs!$B$2:$B$28,$B36,S1_Extracted_pairs!$P$2:$P$28,"yes",S1_Extracted_pairs!$N$2:$N$28,"Academic*") -> 4 | E36: =COUNTIFS(S1_Extracted_pairs!$B$2:$B$28,$B36,S1_Extracted_pairs!$P$2:$P$28,"yes",S1_Extracted_pairs!$N$2:$N$28,"Academic*",S1_Extracted_pairs!$R$2:$R$28,"<1") -> 0
A37: Academic-funded only | B37: S11 | C37: =AVERAGEIFS(S1_Extracted_pairs!$S$2:$S$28,S1_Extracted_pairs!$B$2:$B$28,$B37,S1_Extracted_pairs!$P$2:$P$28,"yes",S1_Extracted_pairs!$N$2:$N$28,"Academic*") -> 3.2072542 | D37: =COUNTIFS(S1_Extracted_pairs!$B$2:$B$28,$B37,S1_Extracted_pairs!$P$2:$P$28,"yes",S1_Extracted_pairs!$N$2:$N$28,"Academic*") -> 2 | E37: =COUNTIFS(S1_Extracted_pairs!$B$2:$B$28,$B37,S1_Extracted_pairs!$P$2:$P$28,"yes",S1_Extracted_pairs!$N$2:$N$28,"Academic*",S1_Extracted_pairs!$R$2:$R$28,"<1") -> 0
A38: Academic-funded only | B38: S13 | C38: =AVERAGEIFS(S1_Extracted_pairs!$S$2:$S$28,S1_Extracted_pairs!$B$2:$B$28,$B38,S1_Extracted_pairs!$P$2:$P$28,"yes",S1_Extracted_pairs!$N$2:$N$28,"Academic*") -> -0.066917883 | D38: =COUNTIFS(S1_Extracted_pairs!$B$2:$B$28,$B38,S1_Extracted_pairs!$P$2:$P$28,"yes",S1_Extracted_pairs!$N$2:$N$28,"Academic*") -> 2 | E38: =COUNTIFS(S1_Extracted_pairs!$B$2:$B$28,$B38,S1_Extracted_pairs!$P$2:$P$28,"yes",S1_Extracted_pairs!$N$2:$N$28,"Academic*",S1_Extracted_pairs!$R$2:$R$28,"<1") -> 1
A39: All excl. Saleh (extreme ratios) | B39: S1 | C39: =AVERAGEIFS(S1_Extracted_pairs!$S$2:$S$28,S1_Extracted_pairs!$B$2:$B$28,$B39,S1_Extracted_pairs!$P$2:$P$28,"yes") -> 0.78322613 | D39: =COUNTIFS(S1_Extracted_pairs!$B$2:$B$28,$B39,S1_Extracted_pairs!$P$2:$P$28,"yes") -> 3 | E39: =COUNTIFS(S1_Extracted_pairs!$B$2:$B$28,$B39,S1_Extracted_pairs!$P$2:$P$28,"yes",S1_Extracted_pairs!$R$2:$R$28,"<1") -> 1
A40: All excl. Saleh (extreme ratios) | B40: S2 | C40: =AVERAGEIFS(S1_Extracted_pairs!$S$2:$S$28,S1_Extracted_pairs!$B$2:$B$28,$B40,S1_Extracted_pairs!$P$2:$P$28,"yes") -> 0.56703818 | D40: =COUNTIFS(S1_Extracted_pairs!$B$2:$B$28,$B40,S1_Extracted_pairs!$P$2:$P$28,"yes") -> 1 | E40: =COUNTIFS(S1_Extracted_pairs!$B$2:$B$28,$B40,S1_Extracted_pairs!$P$2:$P$28,"yes",S1_Extracted_pairs!$R$2:$R$28,"<1") -> 0
...

Sheet S3_Model_parameters
A1: parameter | B1: symbol | C1: low | D1: base | E1: high | F1: unit | G1: status | H1: source
A2: Primary aluminium cradle-to-gate | B2: V_Al | C2: 15.1 | D2: 15.1 | E2: 19.6 | F2: kg CO2e/kg | G2: sourced | H2: IAI 2022 global 15.1; India ~19.6 (LSE Grantham Institute)
A3: Recycled aluminium (gate-to-gate) | B3: S_Al | C3: 0.52 | D3: 0.52 | E3: 1 | F3: kg CO2e/kg | G3: sourced (low); high assumed | H3: IAI factsheet 0.52
A4: Aluminium recycling yield | B4: y_Al | C4: 0.9 | D4: 0.98 | E4: 0.98 | F4: fraction | G4: sourced | H4: TERI 2022 Table 15 (98%)
A5: Aluminium can-making overhead | B5: conv_Al | C5: 0.5 | D5: 1 | E5: 2 | F5: kg CO2e/kg | G5: assumed | H5: No source found - sensitivity range
A6: Virgin container glass | B6: V_G | C6: 1 | D6: 1.1 | E6: 1.5 | F6: kg CO2e/kg | G6: derived/assumed | H6: Derived from FEVE: 1 t cullet saves ~0.58-0.67 t CO2 vs ~58% saving at 100% cullet -> ~1.0; India upper bound assumed
A7: Glass credit per kg recycled (cullet) | B7: dV_G | C7: 0.58 | D7: 0.58 | E7: 0.67 | F7: kg CO2e/kg | G7: sourced | H7: FEVE brochure / FEVE 2026 (580-670 kg per t)
A8: Glass recycling yield | B8: y_G | C8: 0.9 | D8: 0.9 | E8: 0.9 | F8: fraction | G8: sourced | H8: TERI 2022 Table 15
A9: Virgin PET resin | B9: V_PET | C9: 2.2 | D9: 2.8 | E9: 3.4 | F9: kg CO2e/kg | G9: sourced (high); low assumed | H9: Hopewell et al. 2009 Table 3 (3.4); low bound modern-resin assumption
A10: Recycled PET flake | B10: S_PET | C10: 1 | D10: 1.4 | E10: 1.8 | F10: kg CO2e/kg | G10: sourced (base) | H10: Hopewell et al. 2009 (typical recycled plastic 1.4)
A11: PET recycling yield | B11: y_PET | C11: 0.85 | D11: 0.85 | E11: 0.85 | F11: fraction | G11: sourced | H11: TERI 2022 Table 15
A12: PET credit quality (open-loop/fibre) | B12: q_PET | C12: 0.3 | D12: 0.5 | E12: 1 | F12: fraction | G12: assumed | H12: Food-grade rPET barred in India at TERI study time (FSSAI)
A13: PET conversion (preform + blow moulding) | B13: conv_PET | C13: 0.2 | D13: 0.5 | E13: 1 | F13: kg CO2e/kg | G13: assumed | H13: No source found - sensitivity range
... A17: Truck transport EF | B17: EF_t | C17: 0.07 | D17: 0.15 | E17: 0.2 | F17: kg CO2e/t-km | G17: assumed | H17: No source found - sensitivity range
A18: Distances Al/PET/glass | B18: D | C18: 1000/500/500 | F18: km | G18: sourced | H18: TERI 2022 Table 6
A19: Mass per litre Al can 500 mL | B19: m_Al | C19: 29.84 | D19: 29.84 | E19: 29.84 | F19: g/L | G19: sourced | H19: TERI 2022 Table 8 (2 x (12.42+2.5) g)
A20: Mass per litre PET 600 mL | B20: m_PET | C20: 39.7 | D20: 39.7 | E20: 39.7 | F20: g/L | G20: sourced | H20: TERI 2022 Table 8 (1.667 x (22.2+1.6) g)
A21: Mass per litre glass 650 mL | B21: m_G | C21: 788 | D21: 788 | E21: 788 | F21: g/L | G21: sourced | H21: TERI 2022 Table 8 (1.538 x (510+2.22) g)
A22: Collection EU PET | B22: c_PET_EU | C22: 0.483 | D22: 0.483 | E22: 0.483 | F22: fraction | G22: sourced | H22: NCL/PACE 2017 report (Europe 48.3%)
A23: Collection EU glass | B23: c_G_EU | C23: 0.801 | D23: 0.801 | E23: 0.801 | F23: fraction | G23: sourced | H23: FEVE 2026 (80.1%)
A24: Collection EU/global Al | B24: c_Al_EU | C24: 0.71 | D24: 0.71 | E24: 0.71 | F24: fraction | G24: sourced (global) | H24: IAI 2019 global can recycling 71%
A25: Collection India Al/PET/glass | B25: c_IN | C25: 0.85/0.70/0.60 | F25: fraction | G25: sourced | H25: TERI 2022 Table 15
A26: Collection India PET alt (NCL) | B26: c_PET_IN_hi | C26: 0.9 | D26: 0.9 | E26: 0.9 | F26: fraction | G26: sourced | H26: CSIR-NCL/PACE 2017 (~90% incl. informal+home reuse)

Sheet S4_Model_scenarios
A1: scenario | B1: Al_med | C1: Al_p5 | D1: Al_p95 | E1: PET_med | F1: PET_p5 | G1: PET_p95 | H1: Glass_med | I1: Glass_p5 | J1: Glass_p95 | K1: AlPET_ratio_med | L1: AlPET_p5 | M1: AlPET_p95 | N1: GlassPET_ratio_med | O1: GlassPET_p5 | P1: GlassPET_p95 | Q1: P_Al_beats_PET | R1: P_Glass_beats_PET
A2: Europe-default rates | B2: 0.21184319 | C2: 0.18927619 | D2: 0.23991025 | E2: 0.12256207 | F2: 0.10571624 | G2: 0.14047658 | H2: 0.64244024 | I2: 0.53293608 | J2: 0.81287892 | K2: 1.7309266 | L2: 1.449648 | M2: 2.0930016 | N2: 5.2759325 | O2: 4.1513872 | P2: 6.901304 | Q2: 0 | R2: 0
A3: India (TERI 2022 rates) | B3: 0.14865525 | C3: 0.12844825 | D3: 0.1735114 | E3: 0.12917904 | F3: 0.11114116 | G3: 0.14813128 | H3: 0.72961295 | I3: 0.62083618 | J3: 0.89946881 | K3: 1.1504887 | L3: 0.94182699 | M3: 1.4253423 | N3: 5.6821767 | O3: 4.5628535 | P3: 7.2811895 | Q3: 0.124 | R3: 0
A4: India (PET 90%, NCL) | B4: 0.14865525 | C4: 0.12844825 | D4: 0.1735114 | E4: 0.11501625 | F4: 0.097333333 | G4: 0.1333925 | H4: 0.72961295 | I4: 0.62083618 | J4: 0.89946881 | K4: 1.2932096 | L4: 1.0489906 | M4: 1.6194612 | N4: 6.3900675 | O4: 5.0792785 | P4: 8.2650329 | Q4: 0.02085 | R4: 0

Sheet S5_Sensitivity
A1: parameter | B1: spearman_rho_with_Al_over_PET
A2: conv_Al | B2: 0.47597074
A3: V_PET | B3: -0.3822825
A4: conv_PET | B4: -0.38007424
A5: y_Al | B5: -0.37998323
A6: V_Al | B6: 0.31039456
A7: q_PET | B7: 0.27918354
A8: b_IN | B8: -0.22713151
A9: S_Al | B9: 0.14801339
A10: S_PET | B10: -0.12861035
A11: V_G | B11: -0.0047931124
A12: EF | B12: 0.0023310395
A13: dV_G | B13: 0.00079166172

Sheet S6_Crossover
A1: case | B1: median_all | C1: p5 | D1: p95 | E1: share_never | F1: share_always | G1: median_inside | H1: AlPET_ratio_med | I1: P_Al_beats_PET | J1: cstar_med | K1: cstar_p5 | L1: cstar_p95
A2: Crossover, PET 70% | B2: 0.89281005 | C2: 0.83142153 | D2: 0.95872684 | E2: 0.00435 | F2: 0 | G2: 0.89257056
A3: Crossover, PET 90% | B3: 0.92425203 | C3: 0.86392029 | D3: 0.98951996 | E3: 0.02965 | F3: 0 | G3: 0.92283083
A4: Al-favourable corner | C4: 0.75441465 | D4: 1.0474098 | H4: 0.88021204 | I4: 0.88955 | J4: 0.81145438 | K4: 0.76171499 | L4: 0.86403066

Sheet S7_References
A1: ref_no | B1: author / organisation | C1: title / venue | D1: link / doi | E1: what it was used for | F1: where used in report
A2: [1] | B2: Dolci et al. (2025) | C2: Waste Management & Research 43(3):339-357 | D2: doi:10.1177/0734242X241241606 | E2: Review of 53 packaging LCAs: plastics often not the worst option; EoL assumptions drive results; single-use PET beats refillable glass below ~10 reuses | F2: Introduction, Discussion, Next steps
A3: [2] | B3: TERI (2022), for Ball Corporation | C3: Sustainable Beverage Packaging Options in India: A Comparative LCA | D3: https://www.teriin.org/sites/default/files/2022-06/Sustainable-Beverage-Packaging-Final-Report.pdf | E3: Indian collection-for-recycling rates (Al 85%, PET 70%, glass 60%, carton 54%); masses (Table 8), distances (Table 6), yields (Table 15); pairs P10-P11 | F3: Stage 1 (P10, P11), Stage 2 inputs, Discussion
A4: [3] | B4: De Feo, Marmora et al. | C4: Eco-efficiency of bottled water packaging | D4: https://www.iris.unisa.it/handle/11386/4958656 | E4: Italian mineral-water LCA: PET 198, glass 933, can 513, carton 170 kg CO2e per 1000 L; pairs P01-P03; EU validation anchor | F4: Stage 1 (S1), Stage 2 validation
A5: [4] | B5: Ferrara & De Feo (2023) | C5: Sustainability 15(4):3665 | D5: doi:10.3390/su15043665; https://www.iris.unisa.it/handle/11386/4840897 | E5: Olive-oil packaging LCA (r-PET vs glass); pair P04 | F5: Stage 1 (S2)
A6: [5] | B6: NAPCOR (2023) | C6: PET vs glass and aluminium LCA, press release (study by Franklin Associates per trade press) | D6: https://napcor.com/news/pet-plastic-bottles-have-a-significantly-lower-environmental-impact-compared-to-glass-bottles-and-aluminum-cans/ | E6: PET 74% lower than aluminium can; industry (PET trade body); pair P05 | F6: Stage 1 (S3)
A7: [6] | B7: Saudi Digital Library repository | C7: Right materials for packaging carbonated drinks | D7: https://drepo.sdl.edu.sa/items/b7c25e12-7df5-4086-a117-a66badf9f3b1 | E7: PET 81.52 g vs glass 425.43 g CO2e per litre; pair P06 | F7: Stage 1 (S4)
A8: [7] | B8: iPoint Systems | C8: What's the greenest 1 L packaging? (carton vs PET/HDPE LCA) | D8: https://go.ipoint-systems.com/blog/whats-the-greenest-1-l-packaging-two-powerful-lcas-give-the-answer | E8: Carton 85 g CO2e per litre, 45% below PET and 34% below HDPE; funder not verified; pairs P07-P08 | F8: Stage 1 (S5)
A9: [8] | B9: Gallego-Schmid et al. (2019) | C9: J. Cleaner Production 211:417-427 (via University of Manchester news release) | D9: https://www.manchester.ac.uk/discover/news/takeaway-containers--the-environmental-cost-of-packing-our-favourite-fast-foods | E9: Takeaway containers: EPS = 50% of aluminium and one-third of PP; pair P09 | F9: Stage 1 (S6)
A10: [9] | B10: International Aluminium Institute | C10: Aluminium facts / recycling factsheet | D10: international-aluminium.org | E10: Primary aluminium 15.1 t CO2e/t; recycled 0.52 t/t; global can recycling 71% | F10: Stage 2 inputs
A11: [10] | B11: LSE Grantham Institute | C11: Decarbonising the aluminium sector in India | D11: lse.ac.uk | E11: Indian primary aluminium about 19.6 t CO2e/t | F11: Stage 2 inputs
A12: [11] | B12: FEVE (European Container Glass Federation) | C12: Recycling brochure and 2026 data | D12: feve.org | E12: Glass collection 80.1%; 1 t cullet saves 0.58-0.67 t CO2 | F12: Stage 2 inputs
... A17: [16] | B17: Ferrara, De Feo & Picone (2021) | C17: Recycling 6:50 | D17: https://doi.org/10.3390/recycling6030050 | E17: Mineral-water packaging incl. reusable glass at 7 uses; pairs P26-P27 | F17: Stage 1 (S13)
A19: Note | B19: Reference list as compiled by the team; the report cites these as short author-year tags. Items without a full URL (e.g. [9]-[14]) were cited from secondary pages; confirm before external use.

Sheet S8_Added_checks
A1: group | B1: k_studies | C1: n_pairs | D1: ratio | E1: boot_low | F1: boot_high | G1: t_low | H1: t_high | I1: tau_ln | J1: pred_low | K1: pred_high | L1: pct_pairs_alt_better
A2: All plastic-baseline pairs | B2: 11 | C2: 23 | D2: 2.2277818 | E2: 1.2653724 | F2: 4.2272552 | G2: 1.0839838 | H2: 4.5784924 | I2: 1.0722739 | J2: 0.18370839 | K2: 27.015705 | L2: 30.434783
A3: Excl. Saleh (S11, extreme) | B3: 10 | C3: 21 | D3: 1.7513407 | E3: 1.1211311 | F3: 2.7231064 | G3: 1.0205772 | H3: 3.0053523 | I3: 0.7548864 | J3: 0.29210569 | K3: 10.500289 | L3: 33.333333
A4: Excl. Pasqualino (S9, different beverages) | B4: 10 | C4: 21 | D4: 2.1055543 | E4: 1.1595062 | F4: 4.2169429 | G4: 0.94974528 | H4: 4.6679453 | I4: 1.1129273 | J4: 0.15018016 | K4: 29.520271 | L4: 33.333333
A5: Excl. S9 and S11 | B5: 9 | C5: 19 | D5: 1.601512 | E5: 1.0271507 | F5: 2.5494918 | G5: 0.90512422 | H5: 2.833689 | I5: 0.7423637 | J5: 0.26354101 | K5: 9.7322257 | L5: 36.842105
A6: Excl. second-hand values (S9-S12 via Stefanini Table 1) | B6: 8 | C6: 15 | D6: 1.5597636 | E6: 0.95422306 | F6: 2.624854 | G6: 0.80641391 | H6: 3.0168904 | I6: 0.78908599 | J6: 0.21555419 | K6: 11.286546 | L6: 46.666667
A7: Glass vs plastic | B7: 6 | C7: 7 | D7: 4.9904698 | E7: 2.3783057 | F7: 14.324535 | G7: 1.3083013 | H7: 19.035973 | I7: 1.2757337 | J7: 0.14448162 | K7: 172.37341 | L7: 0
A8: Aluminium vs plastic | B8: 6 | C8: 7 | D8: 3.2084978 | E8: 1.4614821 | F8: 7.0438485 | G8: 1.0198668 | H8: 10.093924 | I8: 1.0921401 | J8: 0.15465257 | K8: 66.565064 | L8: 14.285714
A9: Carton vs plastic | B9: 3 | C9: 4 | D9: 0.90835325 | E9: 0.60255508 | F9: 1.4487179 | G9: 0.30347518 | H9: 2.7188571 | I9: 0.44133363 | J9: 0.10138917 | K9: 8.1380054 | L9: 75
A10: Reusable glass vs plastic | B10: 2 | C10: 4 | D10: 0.99316467 | E10: 0.935272 | F10: 1.0546408 | G10: 0.46302151 | H10: 2.1303029 | I10: 0.084936366 | J10: 0.26484075 | K10: 3.7244119 | L10: 50
A12: Added in analysis v2. Equal-weight random-effects-style summary: study-level mean of ln ratio, t-interval, between-study SD (tau_ln) and 95% prediction interval.
A13: Within-study variances are not available from abstracts, so studies are weighted equally.
A14: Corrections to rounding in the earlier draft: P(Al lower than PET) at Indian TERI rates is 12.4% (12%, not 13%); in the aluminium-favourable corner it is 89.0% (89%, not 88%).
A15: Robustness: the pooled ratio falls from 2.2 to 1.6 (and its interval reaches 1) once the second-hand / different-beverage / extreme values (S9-S12) are removed.
A17: Workbook changes in this version: sheet 1 ratio and ln_ratio are formulas, plus a comparability_caveat column; sheet 2 has a live formula block (using helper sheet 2b); sheet 3 low values stored as numbers; sheet 5 header named; sheet 9 is a live base-case model.
A18: Sheets 4, 5 and 6 are Monte Carlo output from analysis.py and are static values by nature.

Sheet S9_Base_case_model
A1: Deterministic base-case version of the Stage 2 model (live formulas), using the BASE (most likely) value of every input in sheet S3. Results sit below the Monte Carlo medians in S4 (e.g. India Al/PET 0.93 here vs 1.15 in S4) because several ranges are right-skewed (e.g. primary aluminium 15.1-19.6): at the modal values aluminium is marginally ahead of PET, over the full ranges it is marginally behind. Either way it is close to parity.
A3: Inputs
A4: symbol | B4: value | C4: unit / note
A5: V_Al | B5: =S3_Model_parameters!D2 -> 15.1 | C5: kg CO2e/kg (linked to sheet 3)
A6: S_Al | B6: =S3_Model_parameters!D3 -> 0.52 | C6: kg CO2e/kg (linked to sheet 3)
A7: y_Al | B7: =S3_Model_parameters!D4 -> 0.98 | C7: fraction (linked to sheet 3)
A8: conv_Al | B8: =S3_Model_parameters!D5 -> 1 | C8: kg CO2e/kg (assumed) (linked to sheet 3)
A9: V_G | B9: =S3_Model_parameters!D6 -> 1.1 | C9: kg CO2e/kg (linked to sheet 3)
A10: dV_G | B10: =S3_Model_parameters!D7 -> 0.58 | C10: kg CO2e/kg (linked to sheet 3)
A11: y_G | B11: =S3_Model_parameters!D8 -> 0.9 | C11: fraction (linked to sheet 3)
A12: V_PET | B12: =S3_Model_parameters!D9 -> 2.8 | C12: kg CO2e/kg (linked to sheet 3)
A13: S_PET | B13: =S3_Model_parameters!D10 -> 1.4 | C13: kg CO2e/kg (linked to sheet 3)
A14: y_PET | B14: =S3_Model_parameters!D11 -> 0.85 | C14: fraction (linked to sheet 3)
A15: q_PET | B15: =S3_Model_parameters!D12 -> 0.5 | C15: fraction (assumed) (linked to sheet 3)
A16: conv_PET | B16: =S3_Model_parameters!D13 -> 0.5 | C16: kg CO2e/kg (assumed) (linked to sheet 3)
... A20: EF_t | B20: =S3_Model_parameters!D17 -> 0.15 | C20: kg CO2e per tonne-km (assumed) (linked to sheet 3)
A21: m_Al | B21: =S3_Model_parameters!D19 -> 29.84 | C21: g per litre (linked to sheet 3)
A22: m_PET | B22: =S3_Model_parameters!D20 -> 39.7 | C22: g per litre (linked to sheet 3)
A23: m_G | B23: =S3_Model_parameters!D21 -> 788 | C23: g per litre (linked to sheet 3)
A24: D_Al_km | B24: 1000 | C24: km, TERI 2022 Table 6
A25: D_PET_km | B25: 500 | C25: km, TERI 2022 Table 6
A26: D_G_km | B26: 500 | C26: km, TERI 2022 Table 6
A27: Scenarios (edit the blue collection rates to test any value)
A28: scenario | B28: Al collection | C28: glass collection | D28: PET collection | E28: PET burned share b | F28: GWP Al can (kg CO2e/L) | G28: GWP PET (kg CO2e/L) | H28: GWP glass (kg CO2e/L) | I28: Al / PET | J28: Glass / PET | K28: Al-PET parity: Al collection c*
A29: Europe-default rates | B29: 0.71 | C29: 0.801 | D29: 0.483 | E29: =$B$19 -> 0 | F29: =($B$21/1000)*($B$5+$B$8)-($B$21/1000)*B29*$B$7*($B$5-$B$6)+($B$21/1000)*$B$24/1000*$B$20 -> 0.18218024 | G29: =($B$22/1000)*($B$12+$B$16)-($B$22/1000)*D29*$B$14*$B$15*($B$12-$B$13)+($B$22/1000)*(1-D29)*E29*$B$17+($B$22/1000)*$B$25/1000*$B$20 -> 0.12257832 | H29: =($B$23/1000)*$B$9-($B$23/1000)*C29*$B$11*$B$10+($B$23/1000)*$B$26/1000*$B$20 -> 0.59641986 | I29: =F29/G29 -> 1.4862355 | J29: =H29/G29 -> 4.8656229 | K29: =(($B$21/1000)*($B$5+$B$8)+($B$21/1000)*$B$24/1000*$B$20-G29)/(($B$21/1000)*$B$7*($B$5-$B$6)) -> 0.84979057
A30: India, TERI rates | B30: 0.85 | C30: 0.6 | D30: 0.7 | E30: =$B$18 -> 0.5 | F30: =($B$21/1000)*($B$5+$B$8)-($B$21/1000)*B30*$B$7*($B$5-$B$6)+($B$21/1000)*$B$24/1000*$B$20 -> 0.12248902 | G30: =($B$22/1000)*($B$12+$B$16)-($B$22/1000)*D30*$B$14*$B$15*($B$12-$B$13)+($B$22/1000)*(1-D30)*E30*$B$17+($B$22/1000)*$B$25/1000*$B$20 -> 0.1310894 | H30: =($B$23/1000)*$B$9-($B$23/1000)*C30*$B$11*$B$10+($B$23/1000)*$B$26/1000*$B$20 -> 0.6790984 | I30: =F30/G30 -> 0.93439304 | J30: =H30/G30 -> 5.1804219 | K30: =(($B$21/1000)*($B$5+$B$8)+($B$21/1000)*$B$24/1000*$B$20-G30)/(($B$21/1000)*$B$7*($B$5-$B$6)) -> 0.82982864
A31: India, PET collected at 90% | B31: 0.85 | C31: 0.6 | D31: 0.9 | E31: =$B$18 -> 0.5 | F31: =($B$21/1000)*($B$5+$B$8)-($B$21/1000)*B31*$B$7*($B$5-$B$6)+($B$21/1000)*$B$24/1000*$B$20 -> 0.12248902 | G31: =($B$22/1000)*($B$12+$B$16)-($B$22/1000)*D31*$B$14*$B$15*($B$12-$B$13)+($B$22/1000)*(1-D31)*E31*$B$17+($B$22/1000)*$B$25/1000*$B$20 -> 0.1172738 | H31: =($B$23/1000)*$B$9-($B$23/1000)*C31*$B$11*$B$10+($B$23/1000)*$B$26/1000*$B$20 -> 0.6790984 | I31: =F31/G31 -> 1.0444705 | J31: =H31/G31 -> 5.7907086 | K31: =(($B$21/1000)*($B$5+$B$8)+($B$21/1000)*$B$24/1000*$B$20-G31)/(($B$21/1000)*$B$7*($B$5-$B$6)) -> 0.8622318
A32: Formulas: Al = m(V+conv) - m*c*y*(V-S) + transport; glass = m*V - m*c*y*dV + transport; PET = m(V+conv) - m*c*y*q*(V-S) + m(1-c)*b*burn + transport; parity c* = (Al at zero collection - PET)/(m*y*(V-S)).
