Workbook

Sheet README
A1: UNWRAP: Unpacking Whether Replacement Alternatives Perform (final data and results workbook)
A2: CM617 course project. Files: analysis.py (all analysis and figures), build_workbook.py (this workbook), paired_comparisons.csv (input data).
A4: Colour code: blue = input you can edit; black = formula or Python result; green = value linked from another sheet.
A5: Live sheets: S1 ratios, S2b and the lower block of S2 recalculate when GWP values in S1 change; S10 and S12 recalculate from S6 and S11.
A6: Bootstrap and Monte Carlo results (S2 top, S3, S4, S7 to S9, S12 top) come from analysis.py and update only when it is rerun.
A8: Data: 46 pairs from 23 studies; core pool 31 pairs from 16 studies.
A9: Pool codes (S1 column 'pool'): core = plastic baseline, format switch, same product, FMCG; sensitivity = added only in sensitivity runs;
A10: refill/reuse = same-material reuse or refill vs single-use (reported separately); not pooled = no plastic baseline or not a format switch.
A12: CHANGES FROM THE PREVIOUS VERSION (v4 report / v2 code)
A13: 1. Added 10 studies (19 pairs): c7-consult/ALPLA, Wohner & Tacker, Wohner PeerJ, Simon, Bertolini, BIO IS, Elopak, Kim & Park, Krohnert & Stucki, Japanese shampoo LCA; plus TERI PET vs returnable glass.
A14: 2. Added home care and personal care pairs (detergent pods pouch, shampoo refills) and a new Pouch/refill class, as promised in the abstract.
A15: 3. Headline now uses a clean core pool: Saleh (likely unit error), Pasqualino (different beverages), the takeaway tray (not FMCG) and the 30-use extra scenario moved to sensitivity.
... A28: Remaining caveats: 18 values come from the ACE 2020 compilation (commissioned by the beverage carton industry); they match that table but the original papers were not all accessible. Replace scoping record counts with database export counts if available.

Sheet S1_Extracted_pairs
A1: pair_id | B1: study_id | C1: short_name | D1: study | E1: year | F1: region | G1: region_group | H1: sector | I1: product_group | J1: functional_unit | K1: conventional | L1: alternative | M1: gwp_conventional | N1: gwp_alternative | O1: ratio_alt_over_conv | P1: ln_ratio | Q1: unit | R1: how_value_obtained | S1: data_source | T1: boundary | U1: unit_basis | V1: eol_stated | W1: sponsor_type | X1: funder_group | Y1: sponsor_material | Z1: best_material_in_study | AA1: sponsor_favours | AB1: alt_class | AC1: pool | AD1: pool_reason | AE1: comparability_caveat | AF1: source_url
A2: P01 | B2: S1 | C2: De Feo | D2: De Feo et al. (mineral water eco-efficiency) | E2: n/r | F2: Italy | G2: Europe | H2: Bottled water | I2: Beverage | J2: 1000 L | K2: PET 0.5 L | L2: Glass one-way 0.5 L | M2: 198 | N2: 933 | O2: =N2/M2 -> 4.7121212 | P2: =LN(O2) -> 1.5501382 | Q2: kg CO2e | R2: Reported directly in abstract | S2: abstract/summary | T2: n/r | U2: per volume | V2: no | W2: Academic | X2: Academic | AB2: Glass | AC2: core | AF2: https://www.iris.unisa.it/handle/11386/4958656
A3: P02 | B3: S1 | C3: De Feo | D3: De Feo et al. (mineral water eco-efficiency) | E3: n/r | F3: Italy | G3: Europe | H3: Bottled water | I3: Beverage | J3: 1000 L | K3: PET 0.5 L | L3: Aluminium can 0.33 L | M3: 198 | N3: 513 | O3: =N3/M3 -> 2.5909091 | P3: =LN(O3) -> 0.95200881 | Q3: kg CO2e | R3: Reported directly in abstract | S3: abstract/summary | T3: n/r | U3: per volume | V3: no | W3: Academic | X3: Academic | AB3: Aluminium | AC3: core | AF3: https://www.iris.unisa.it/handle/11386/4958656
A4: P03 | B4: S1 | C4: De Feo | D4: De Feo et al. (mineral water eco-efficiency) | E4: n/r | F4: Italy | G4: Europe | H4: Bottled water | I4: Beverage | J4: 1000 L | K4: PET 0.5 L | L4: Aseptic carton 0.5 L | M4: 198 | N4: 170 | O4: =N4/M4 -> 0.85858586 | P4: =LN(O4) -> -0.15246859 | Q4: kg CO2e | R4: Reported directly in abstract | S4: abstract/summary | T4: n/r | U4: per volume | V4: no | W4: Academic | X4: Academic | AB4: Carton | AC4: core | AF4: https://www.iris.unisa.it/handle/11386/4958656
A5: P04 | B5: S2 | C5: Ferrara 23 | D5: Ferrara & De Feo | E5: 2023 | F5: Italy/EU destinations | G5: Europe | H5: Olive oil | I5: Food | J5: 1000 L EVOO | K5: 100% recycled PET bottle | L5: Glass bottle | M5: 546.5 | N5: 963.5 | O5: =N5/M5 -> 1.7630375 | P5: =LN(O5) -> 0.56703818 | Q5: kg CO2e | R5: Midpoint of reported ranges (PET 459-634; glass 790-1137) | S5: abstract/summary | T5: n/r | U5: per volume | V5: no | W5: Academic | X5: Academic | AB5: Glass | AC5: core | AF5: https://www.iris.unisa.it/handle/11386/4840897
A6: P05 | B6: S3 | C6: NAPCOR* | D6: NAPCOR LCA (conducted by Franklin Associates per trade press) | E6: 2023 | F6: USA | G6: Outside Europe | H6: Water/CSD | I6: Beverage | J6: per container (16.9 oz PET vs 12 oz can) | K6: PET bottle 16.9 oz | L6: Aluminium can 12 oz | M6: 26 | N6: 100 | O6: =N6/M6 -> 3.8461538 | P6: =LN(O6) -> 1.3470736 | Q6: index (Al=100) | R6: PET reported as 74% lower than Al can; Al set to 100 | S6: abstract/summary | T6: packaging only | U6: per container | V6: no | W6: Industry (PET trade body) | X6: Industry-linked | Y6: PET | Z6: PET | AA6: yes | AB6: Aluminium | AC6: core | AE6: Per container (index, Al can = 100); industry (PET trade body) | AF6: https://napcor.com/news/pet-plastic-bottles-have-a-significantly-lower-environmental-impact-compared-to-glass-bottles-and-aluminum-cans/
A7: P06 | B7: S4 | C7: SDL | D7: Saudi Digital Library repository study (carbonated drinks) | E7: n/r | F7: n/r | G7: Unknown | H7: Carbonated drinks | I7: Beverage | J7: 1 L | K7: PET bottle | L7: Glass bottle | M7: 81.52 | N7: 425.43 | O7: =N7/M7 -> 5.2187193 | P7: =LN(O7) -> 1.652252 | Q7: g CO2e | R7: Reported directly in abstract | S7: abstract/summary | T7: n/r | U7: per volume | V7: no | W7: Academic thesis/report | X7: Academic | AB7: Glass | AC7: core | AF7: https://drepo.sdl.edu.sa/items/b7c25e12-7df5-4086-a117-a66badf9f3b1
A8: P07 | B8: S5 | C8: iPoint carton* | D8: Carton-vs-bottle LCA summarised by iPoint (Combibloc carton) | E8: 2021 | F8: n/r (source discusses UK/US pints) | G8: Unknown | H8: Fresh milk | I8: Dairy | J8: 1 L | K8: PET bottle (disposable) | L8: Gable-top carton | M8: 154.5 | N8: 85 | O8: =N8/M8 -> 0.55016181 | P8: =LN(O8) -> -0.59754284 | Q8: g CO2e | R8: Carton 85 g and 45% lower than PET -> PET=85/0.55 | S8: abstract/summary | T8: packaging only | U8: per volume | V8: no | W8: Industry-linked (carton product LCA; funder not verified) | X8: Industry-linked | Y8: Carton | Z8: Carton | AA8: yes | AB8: Carton | AC8: core | AE8: Derived from % difference; funder not verified | AF8: https://go.ipoint-systems.com/blog/whats-the-greenest-1-l-packaging-two-powerful-lcas-give-the-answer
A9: P08 | B9: S5 | C9: iPoint carton* | D9: Carton-vs-bottle LCA summarised by iPoint (Combibloc carton) | E9: 2021 | F9: n/r (source discusses UK/US pints) | G9: Unknown | H9: Fresh milk | I9: Dairy | J9: 1 L | K9: HDPE multilayer bottle | L9: Gable-top carton | M9: 128.8 | N9: 85 | O9: =N9/M9 -> 0.65993789 | P9: =LN(O9) -> -0.41560956 | Q9: g CO2e | R9: Carton 85 g and 34% lower than HDPE -> HDPE=85/0.66 | S9: abstract/summary | T9: packaging only | U9: per volume | V9: no | W9: Industry-linked (carton product LCA; funder not verified) | X9: Industry-linked | Y9: Carton | Z9: Carton | AA9: yes | AB9: Carton | AC9: core | AE9: Derived from % difference; funder not verified | AF9: https://go.ipoint-systems.com/blog/whats-the-greenest-1-l-packaging-two-powerful-lcas-give-the-answer
A10: P09 | B10: S6 | C10: Gallego-S. | D10: Gallego-Schmid et al. | E10: 2019 | F10: EU | G10: Europe | H10: Takeaway food container | I10: Food | J10: per container | K10: PP single-use | L10: Aluminium single-use | M10: 3 | N10: 2 | O10: =N10/M10 -> 0.66666667 | P10: =LN(O10) -> -0.40546511 | Q10: index (EPS=1) | R10: EPS = 50% of Al and one-third of PP -> EPS=1 Al=2 PP=3 | S10: abstract/summary | T10: packaging only | U10: per container | V10: no | W10: Academic | X10: Academic | AB10: Aluminium | AC10: sensitivity | AD10: Foodservice takeaway tray, outside FMCG scope (protocol rule 1) | AE10: Index (EPS = 1) derived from stated percentages; per container | AF10: https://www.manchester.ac.uk/discover/news/takeaway-containers--the-environmental-cost-of-packing-our-favourite-fast-foods
A11: P10 | B11: S7 | C11: TERI* | D11: TERI for Ball Corporation | E11: 2022 | F11: India | G11: Outside Europe | H11: Beer | I11: Beverage | J11: 1 L fill | K11: Glass bottle 650 mL | L11: Aluminium can 500 mL | M11: 3.52 | N11: 1 | O11: =N11/M11 -> 0.28409091 | P11: =LN(O11) -> -1.258461 | Q11: index (can=1) | R11: Text states glass GWP is 3.5x the can (Fig 16 = 352%) | S11: primary full text | T11: packaging only | U11: per volume | V11: yes | W11: Industry (aluminium can maker) | X11: Industry-linked | Y11: Aluminium | Z11: Aluminium | AA11: yes | AB11: Aluminium vs glass | AC11: not pooled | AD11: No plastic baseline (aluminium vs glass) | AE11: Industry (can maker); not pooled | AF11: https://www.teriin.org/sites/default/files/2022-06/Sustainable-Beverage-Packaging-Final-Report.pdf
A12: P11 | B12: S7 | C12: TERI* | D12: TERI for Ball Corporation | E12: 2022 | F12: India | G12: Outside Europe | H12: Beverages | I12: Beverage | J12: 1 L fill | K12: Glass bottle 200 mL | L12: Aluminium can 500 mL | M12: 5.26 | N12: 1 | O12: =N12/M12 -> 0.19011407 | P12: =LN(O12) -> -1.660131 | Q12: index (can=1) | R12: Text: 200 mL glass is 526% of the 500 mL can (Fig 9) | S12: primary full text | T12: packaging only | U12: per volume | V12: yes | W12: Industry (aluminium can maker) | X12: Industry-linked | Y12: Aluminium | Z12: Aluminium | AA12: yes | AB12: Aluminium vs glass | AC12: not pooled | AD12: No plastic baseline (aluminium vs glass) | AE12: Industry (can maker); not pooled | AF12: https://www.teriin.org/sites/default/files/2022-06/Sustainable-Beverage-Packaging-Final-Report.pdf
A13: P12 | B13: S8 | C13: Stefanini | D13: Stefanini et al. (milk bottles) | E13: 2021 | F13: Italy | G13: Europe | H13: Milk | I13: Dairy | J13: 1 L | K13: PET bottle | L13: Glass non-returnable | M13: 0.186 | N13: 0.43 | O13: =N13/M13 -> 2.311828 | P13: =LN(O13) -> 0.83803853 | Q13: kg CO2e | R13: Total GWP from Tables 8 and 10 | S13: primary full text | T13: packaging only | U13: per volume | V13: yes | W13: Academic | X13: Academic | AB13: Glass | AC13: core | AF13: https://doi.org/10.1007/s11367-020-01804-x
A14: P13 | B14: S8 | C14: Stefanini | D14: Stefanini et al. (milk bottles) | E14: 2021 | F14: Italy | G14: Europe | H14: Milk | I14: Dairy | J14: 1 L | K14: PET bottle | L14: Returnable glass (8 uses) | M14: 0.186 | N14: 0.208 | O14: =N14/M14 -> 1.1182796 | P14: =LN(O14) -> 0.11179141 | Q14: kg CO2e | R14: Fig. 9 (8 uses = 2.08E-01) | S14: primary full text | T14: packaging only | U14: per volume | V14: yes | W14: Academic | X14: Academic | AB14: Reusable glass | AC14: core | AF14: https://doi.org/10.1007/s11367-020-01804-x
A15: P14 | B15: S8 | C15: Stefanini | D15: Stefanini et al. (milk bottles) | E15: 2021 | F15: Italy | G15: Europe | H15: Milk | I15: Dairy | J15: 1 L | K15: PET bottle | L15: Returnable glass (30 uses) | M15: 0.186 | N15: 0.185 | O15: =N15/M15 -> 0.99462366 | P15: =LN(O15) -> -0.0053908486 | Q15: kg CO2e | R15: Fig. 9 (30 uses = 1.85E-01) | S15: primary full text | T15: packaging only | U15: per volume | V15: yes | W15: Academic | X15: Academic | AB15: Reusable glass | AC15: sensitivity | AD15: Extra scenario of same study (30 uses); baseline is 8 uses (pair rule) | AF15: https://doi.org/10.1007/s11367-020-01804-x
A16: P15 | B16: S8 | C16: Stefanini | D16: Stefanini et al. (milk bottles) | E16: 2021 | F16: Italy | G16: Europe | H16: Milk | I16: Dairy | J16: 1 L | K16: PET bottle (virgin) | L16: R-PET bottle (50% recycled) | M16: 0.186 | N16: 0.152 | O16: =N16/M16 -> 0.8172043 | P16: =LN(O16) -> -0.20186615 | Q16: kg CO2e | R16: Tables 8 and 9 | S16: primary full text | T16: packaging only | U16: per volume | V16: yes | W16: Academic | X16: Academic | AB16: Recycled PET | AC16: not pooled | AD16: Same format with recycled content, not a packaging switch | AF16: https://doi.org/10.1007/s11367-020-01804-x
A17: P16 | B17: S9 | C17: Pasqualino | D17: Pasqualino et al. (as tabulated in Stefanini 2021 Table 1) | E17: 2011 | F17: Spain | G17: Europe | H17: Beverages | I17: Beverage | J17: 1 L | K17: PET 1.5 L water | L17: Aseptic carton 1 L juice | M17: 0.078 | N17: 0.113 | O17: =N17/M17 -> 1.4487179 | P17: =LN(O17) -> 0.37067899 | Q17: kg CO2e/L | R17: Secondary citation in open-access Table 1 (different beverages) | S17: second-hand table | T17: incl. product | U17: per volume | V17: no | W17: Academic | X17: Academic | AB17: Carton | AC17: sensitivity | AD17: Different beverages (water vs juice) | AE17: Compares different beverages (PET water vs carton juice); second-hand | AF17: https://doi.org/10.1007/s11367-020-01804-x
A18: P17 | B18: S9 | C18: Pasqualino | D18: Pasqualino et al. (as tabulated in Stefanini 2021 Table 1) | E18: 2011 | F18: Spain | G18: Europe | H18: Beverages | I18: Beverage | J18: 1 L | K18: PET 1.5 L water | L18: Aluminium can 0.33 L beer | M18: 0.078 | N18: 0.826 | O18: =N18/M18 -> 10.589744 | P18: =LN(O18) -> 2.3598859 | Q18: kg CO2e/L | R18: Secondary citation in open-access Table 1 (different beverages) | S18: second-hand table | T18: incl. product | U18: per volume | V18: no | W18: Academic | X18: Academic | AB18: Aluminium | AC18: sensitivity | AD18: Different beverages (water vs beer) | AE18: Compares different beverages (PET water vs beer can); second-hand | AF18: https://doi.org/10.1007/s11367-020-01804-x
A19: P18 | B19: S10 | C19: Amienyo | D19: Amienyo et al. (carbonated soft drinks; as tabulated in Stefanini 2021) | E19: 2013 | F19: UK | G19: Europe | H19: Carbonated drinks | I19: Beverage | J19: 1 L | K19: PET 0.5 L | L19: Glass 0.75 L | M19: 0.293 | N19: 0.555 | O19: =N19/M19 -> 1.894198 | P19: =LN(O19) -> 0.6387955 | Q19: kg CO2e/L | R19: Secondary citation in open-access Table 1 | S19: second-hand table | T19: incl. product | U19: per volume | V19: yes | W19: Academic | X19: Academic | AB19: Glass | AC19: core | AE19: Second-hand (Stefanini Table 1) | AF19: https://doi.org/10.1007/s11367-020-01804-x
A20: P19 | B20: S10 | C20: Amienyo | D20: Amienyo et al. (carbonated soft drinks; as tabulated in Stefanini 2021) | E20: 2013 | F20: UK | G20: Europe | H20: Carbonated drinks | I20: Beverage | J20: 1 L | K20: PET 0.5 L | L20: Aluminium can 0.33 L | M20: 0.293 | N20: 0.312 | O20: =N20/M20 -> 1.0648464 | P20: =LN(O20) -> 0.062830579 | Q20: kg CO2e/L | R20: Secondary citation in open-access Table 1 | S20: second-hand table | T20: incl. product | U20: per volume | V20: yes | W20: Academic | X20: Academic | AB20: Aluminium | AC20: core | AE20: Second-hand | AF20: https://doi.org/10.1007/s11367-020-01804-x
A21: P20 | B21: S10 | C21: Amienyo | D21: Amienyo et al. (carbonated soft drinks; as tabulated in Stefanini 2021) | E21: 2013 | F21: UK | G21: Europe | H21: Carbonated drinks | I21: Beverage | J21: 1 L | K21: PET 2 L | L21: Glass 0.75 L | M21: 0.151 | N21: 0.555 | O21: =N21/M21 -> 3.6754967 | P21: =LN(O21) -> 1.3016883 | Q21: kg CO2e/L | R21: Secondary citation in open-access Table 1 | S21: second-hand table | T21: incl. product | U21: per volume | V21: yes | W21: Academic | X21: Academic | AB21: Glass | AC21: core | AE21: Second-hand | AF21: https://doi.org/10.1007/s11367-020-01804-x
A22: P21 | B22: S10 | C22: Amienyo | D22: Amienyo et al. (carbonated soft drinks; as tabulated in Stefanini 2021) | E22: 2013 | F22: UK | G22: Europe | H22: Carbonated drinks | I22: Beverage | J22: 1 L | K22: PET 2 L | L22: Aluminium can 0.33 L | M22: 0.151 | N22: 0.312 | O22: =N22/M22 -> 2.0662252 | P22: =LN(O22) -> 0.72572335 | Q22: kg CO2e/L | R22: Secondary citation in open-access Table 1 | S22: second-hand table | T22: incl. product | U22: per volume | V22: yes | W22: Academic | X22: Academic | AB22: Aluminium | AC22: core | AE22: Second-hand | AF22: https://doi.org/10.1007/s11367-020-01804-x
A23: P22 | B23: S11 | C23: Saleh | D23: Saleh (Palestine; as tabulated in Stefanini 2021) | E23: 2015 | F23: Palestine | G23: Outside Europe | H23: Beverages | I23: Beverage | J23: 1000 L (units as tabulated) | K23: PET 2 L | L23: Glass 0.33 L | M23: 0.044 | N23: 2.57 | O23: =N23/M23 -> 58.409091 | P23: =LN(O23) -> 4.0674715 | Q23: as tabulated (kg CO2e per FU) | R23: Secondary citation in open-access Table 1; extreme ratio - flagged as possible unit issue | S23: second-hand table | T23: n/r | U23: per volume | V23: no | W23: Academic | X23: Academic | AB23: Glass | AC23: sensitivity | AD23: Extreme ratio (58x), likely unit error | AE23: Extreme ratio - possible unit issue; second-hand | AF23: https://doi.org/10.1007/s11367-020-01804-x
A24: P23 | B24: S11 | C24: Saleh | D24: Saleh (Palestine; as tabulated in Stefanini 2021) | E24: 2015 | F24: Palestine | G24: Outside Europe | H24: Beverages | I24: Beverage | J24: 1000 L (units as tabulated) | K24: PET 2 L | L24: Aluminium can 0.33 L | M24: 0.044 | N24: 0.46 | O24: =N24/M24 -> 10.454545 | P24: =LN(O24) -> 2.3470369 | Q24: as tabulated (kg CO2e per FU) | R24: Secondary citation in open-access Table 1; extreme ratio - flagged as possible unit issue | S24: second-hand table | T24: n/r | U24: per volume | V24: no | W24: Academic | X24: Academic | AB24: Aluminium | AC24: sensitivity | AD24: Extreme ratio, likely unit error | AE24: Extreme ratio - possible unit issue; second-hand | AF24: https://doi.org/10.1007/s11367-020-01804-x
A25: P24 | B25: S12 | C25: Mata&Costa | D25: Mata & Costa (beer bottles; as tabulated in Stefanini 2021) | E25: 2001 | F25: Portugal | G25: Europe | H25: Beer | I25: Beverage | J25: 0.33 L bottle | K25: Glass non-returnable (cycle 1) | L25: Glass returnable (cycle 1) | M25: 0.12 | N25: 0.13 | O25: =N25/M25 -> 1.0833333 | P25: =LN(O25) -> 0.080042708 | Q25: kg CO2e/L | R25: Secondary citation in open-access Table 1 | S25: second-hand table | T25: n/r | U25: per container | V25: no | W25: Academic | X25: Academic | AB25: Reuse vs single-use | AC25: not pooled | AD25: Cycle 1 = bottle not yet reused | AE25: Second-hand; not pooled | AF25: https://doi.org/10.1007/s11367-020-01804-x
A26: P25 | B26: S12 | C26: Mata&Costa | D26: Mata & Costa (beer bottles; as tabulated in Stefanini 2021) | E26: 2001 | F26: Portugal | G26: Europe | H26: Beer | I26: Beverage | J26: 0.33 L bottle | K26: Glass non-returnable (cycle 6) | L26: Glass returnable (cycle 6) | M26: 0.59 | N26: 0.28 | O26: =N26/M26 -> 0.47457627 | P26: =LN(O26) -> -0.74533293 | Q26: kg CO2e/L | R26: Secondary citation in open-access Table 1 | S26: second-hand table | T26: n/r | U26: per container | V26: no | W26: Academic | X26: Academic | AB26: Reuse vs single-use | AC26: refill/reuse | AD26: Same-material reuse vs single-use (no plastic baseline) | AE26: Second-hand; not pooled | AF26: https://doi.org/10.1007/s11367-020-01804-x
A27: P26 | B27: S13 | C27: Ferrara 21 | D27: Ferrara et al. (mineral water) | E27: 2021 | F27: Italy | G27: Europe | H27: Natural water | I27: Beverage | J27: 1 L | K27: PET 1 L | L27: Reusable glass (7 uses) | M27: 188.6 | N27: 190.6 | O27: =N27/M27 -> 1.0106045 | P27: =LN(O27) -> 0.010548621 | Q27: g CO2e | R27: Sum of stage values in Fig. 4a | S27: primary full text | T27: n/r | U27: per volume | V27: no | W27: Academic | X27: Academic | AB27: Reusable glass | AC27: core | AF27: https://doi.org/10.3390/recycling6030050
A28: P27 | B28: S13 | C28: Ferrara 21 | D28: Ferrara et al. (mineral water) | E28: 2021 | F28: Italy | G28: Europe | H28: Sparkling water | I28: Beverage | J28: 1 L | K28: PET 1 L | L28: Reusable glass (7 uses) | M28: 191.9 | N28: 166.1 | O28: =N28/M28 -> 0.86555498 | P28: =LN(O28) -> -0.14438439 | Q28: g CO2e | R28: Sum of stage values in Fig. 4a | S28: primary full text | T28: n/r | U28: per volume | V28: no | W28: Academic | X28: Academic | AB28: Reusable glass | AC28: core | AF28: https://doi.org/10.3390/recycling6030050
A29: P28 | B29: S14 | C29: c7-consult* | D29: c7-consult for ALPLA (milk and juice bottles; via ACE 2020) | E29: 2019 | F29: Austria | G29: Europe | H29: Milk | I29: Dairy | J29: 1 L | K29: PET bottle 1 L | L29: Beverage carton 1 L | M29: 117 | N29: 83 | O29: =N29/M29 -> 0.70940171 | P29: =LN(O29) -> -0.34333333 | Q29: g CO2e/L | R29: Second-hand, checked against ACE 2020 Tables 1-2 (ref 7) | S29: second-hand table | T29: packaging only | U29: per volume | V29: no | W29: Industry (PET bottle maker ALPLA) | X29: Industry-linked | Y29: PET | Z29: Carton | AA29: no | AB29: Carton | AC29: core | AF29: Wohner & Tacker 2020 (Circular Analytics for ACE) Tables 1-4; https://www.tetrapak.com/content/dam/tetrapak/publicweb/gb/en/sustainability/20-011-Circular-Analytics_ACE-Full-report_2021-01-25.pdf
A30: P29 | B30: S14 | C30: c7-consult* | D30: c7-consult for ALPLA (milk and juice bottles; via ACE 2020) | E30: 2019 | F30: Austria | G30: Europe | H30: Milk | I30: Dairy | J30: 1 L | K30: PET bottle 1 L | L30: Glass one-way 1 L | M30: 117 | N30: 335 | O30: =N30/M30 -> 2.8632479 | P30: =LN(O30) -> 1.0519566 | Q30: g CO2e/L | R30: Second-hand, checked against ACE 2020 Tables 2-3 | S30: second-hand table | T30: packaging only | U30: per volume | V30: no | W30: Industry (PET bottle maker ALPLA) | X30: Industry-linked | Y30: PET | Z30: Carton | AA30: no | AB30: Glass | AC30: core | AF30: Wohner & Tacker 2020 (Circular Analytics for ACE) Tables 1-4; https://www.tetrapak.com/content/dam/tetrapak/publicweb/gb/en/sustainability/20-011-Circular-Analytics_ACE-Full-report_2021-01-25.pdf
A31: P30 | B31: S14 | C31: c7-consult* | D31: c7-consult for ALPLA (milk and juice bottles; via ACE 2020) | E31: 2019 | F31: Austria | G31: Europe | H31: Milk | I31: Dairy | J31: 1 L | K31: PET bottle 1 L | L31: Reusable glass 1 L | M31: 117 | N31: 114 | O31: =N31/M31 -> 0.97435897 | P31: =LN(O31) -> -0.025975486 | Q31: g CO2e/L | R31: Second-hand, checked against ACE 2020 Tables 2 and 4 | S31: second-hand table | T31: packaging only | U31: per volume | V31: no | W31: Industry (PET bottle maker ALPLA) | X31: Industry-linked | Y31: PET | Z31: Carton | AA31: no | AB31: Reusable glass | AC31: core | AF31: Wohner & Tacker 2020 (Circular Analytics for ACE) Tables 1-4; https://www.tetrapak.com/content/dam/tetrapak/publicweb/gb/en/sustainability/20-011-Circular-Analytics_ACE-Full-report_2021-01-25.pdf
A32: P31 | B32: S14 | C32: c7-consult* | D32: c7-consult for ALPLA (milk and juice bottles; via ACE 2020) | E32: 2019 | F32: Austria | G32: Europe | H32: Juice | I32: Beverage | J32: 1 L (scaled from 0.5 L) | K32: PET bottle 0.5 L | L32: Glass one-way 0.5 L | M32: 160 | N32: 548 | O32: =N32/M32 -> 3.425 | P32: =LN(O32) -> 1.2311015 | Q32: g CO2e/L | R32: Second-hand, checked against ACE 2020 Tables 2-3 | S32: second-hand table | T32: packaging only | U32: per volume | V32: no | W32: Industry (PET bottle maker ALPLA) | X32: Industry-linked | Y32: PET | Z32: Carton | AA32: no | AB32: Glass | AC32: core | AF32: Wohner & Tacker 2020 (Circular Analytics for ACE) Tables 1-4; https://www.tetrapak.com/content/dam/tetrapak/publicweb/gb/en/sustainability/20-011-Circular-Analytics_ACE-Full-report_2021-01-25.pdf
A33: P32 | B33: S14 | C33: c7-consult* | D33: c7-consult for ALPLA (milk and juice bottles; via ACE 2020) | E33: 2019 | F33: Austria | G33: Europe | H33: Juice | I33: Beverage | J33: 1 L (scaled from 0.5 L) | K33: PET bottle 0.5 L | L33: Reusable glass 0.5 L | M33: 160 | N33: 138 | O33: =N33/M33 -> 0.8625 | P33: =LN(O33) -> -0.14792013 | Q33: g CO2e/L | R33: Second-hand, checked against ACE 2020 Tables 2 and 4 | S33: second-hand table | T33: packaging only | U33: per volume | V33: no | W33: Industry (PET bottle maker ALPLA) | X33: Industry-linked | Y33: PET | Z33: Carton | AA33: no | AB33: Reusable glass | AC33: core | AF33: Wohner & Tacker 2020 (Circular Analytics for ACE) Tables 1-4; https://www.tetrapak.com/content/dam/tetrapak/publicweb/gb/en/sustainability/20-011-Circular-Analytics_ACE-Full-report_2021-01-25.pdf
A34: P33 | B34: S15 | C34: Wohner&Tacker | D34: Wohner & Tacker (milk packaging; via ACE 2020) | E34: 2019 | F34: Austria | G34: Europe | H34: Milk | I34: Dairy | J34: 1 L | K34: PET bottle 1 L | L34: Glass one-way 1 L | M34: 163 | N34: 256 | O34: =N34/M34 -> 1.5705521 | P34: =LN(O34) -> 0.45142724 | Q34: g CO2e/L | R34: Second-hand, checked against ACE 2020 Tables 2-3 (ref 8); carton value under NDA | S34: second-hand table | T34: packaging only | U34: per volume | V34: no | W34: Unclear | X34: Other/unclear | AB34: Glass | AC34: core | AF34: Wohner & Tacker 2020 (Circular Analytics for ACE) Tables 1-4; https://www.tetrapak.com/content/dam/tetrapak/publicweb/gb/en/sustainability/20-011-Circular-Analytics_ACE-Full-report_2021-01-25.pdf
A35: P34 | B35: S16 | C35: Wohner PeerJ | D35: Wohner et al. (PeerJ 7:e7578; via ACE 2020) | E35: 2019 | F35: Austria | G35: Europe | H35: Milk | I35: Dairy | J35: 1 L | K35: Beverage carton 1 L | L35: Glass one-way 1 L | M35: 77 | N35: 448 | O35: =N35/M35 -> 5.8181818 | P35: =LN(O35) -> 1.7609878 | Q35: g CO2e/L | R35: Second-hand, checked against ACE 2020 Tables 1 and 3 (ref 2) | S35: second-hand table | T35: packaging only | U35: per volume | V35: no | W35: Unclear | X35: Other/unclear | AB35: Glass vs carton | AC35: not pooled | AD35: No plastic baseline (carton vs glass) | AF35: https://peerj.com/articles/7578/
A36: P35 | B36: S17 | C36: Simon | D36: Simon, Amor & Foldenyi (J Clean Prod 112:238; via ACE 2020) | E36: 2016 | F36: Hungary | G36: Europe | H36: Beverages | I36: Beverage | J36: 1 L | K36: PET bottle 1 L | L36: Glass one-way 1 L | M36: 151 | N36: 176 | O36: =N36/M36 -> 1.1655629 | P36: =LN(O36) -> 0.15320416 | Q36: g CO2e/L | R36: Second-hand, checked against ACE 2020 Tables 2-3 (ref 4) | S36: second-hand table | T36: packaging only | U36: per volume | V36: no | W36: Academic | X36: Academic | AB36: Glass | AC36: core | AF36: Wohner & Tacker 2020 (Circular Analytics for ACE) Tables 1-4; https://www.tetrapak.com/content/dam/tetrapak/publicweb/gb/en/sustainability/20-011-Circular-Analytics_ACE-Full-report_2021-01-25.pdf
A37: P36 | B37: S17 | C37: Simon | D37: Simon, Amor & Foldenyi (J Clean Prod 112:238; via ACE 2020) | E37: 2016 | F37: Hungary | G37: Europe | H37: Beverages | I37: Beverage | J37: 1 L | K37: PET bottle 1 L | L37: Beverage carton 1 L | M37: 151 | N37: 88 | O37: =N37/M37 -> 0.58278146 | P37: =LN(O37) -> -0.53994302 | Q37: g CO2e/L | R37: Second-hand, checked against ACE 2020 Tables 1-2 | S37: second-hand table | T37: packaging only | U37: per volume | V37: no | W37: Academic | X37: Academic | AB37: Carton | AC37: core | AF37: Wohner & Tacker 2020 (Circular Analytics for ACE) Tables 1-4; https://www.tetrapak.com/content/dam/tetrapak/publicweb/gb/en/sustainability/20-011-Circular-Analytics_ACE-Full-report_2021-01-25.pdf
A38: P37 | B38: S18 | C38: Bertolini | D38: Bertolini et al. (Packag Technol Sci 29:525; via ACE 2020) | E38: 2016 | F38: Italy | G38: Europe | H38: ESL milk | I38: Dairy | J38: 1 L | K38: PET bottle 1 L | L38: Beverage carton 1 L | M38: 165 | N38: 104 | O38: =N38/M38 -> 0.63030303 | P38: =LN(O38) -> -0.46155457 | Q38: g CO2e/L | R38: Second-hand, checked against ACE 2020 Tables 1-2 (ref 5) | S38: second-hand table | T38: packaging only | U38: per volume | V38: no | W38: Academic (funder not verified) | X38: Academic | AB38: Carton | AC38: core | AF38: Wohner & Tacker 2020 (Circular Analytics for ACE) Tables 1-4; https://www.tetrapak.com/content/dam/tetrapak/publicweb/gb/en/sustainability/20-011-Circular-Analytics_ACE-Full-report_2021-01-25.pdf
A39: P38 | B39: S19 | C39: BIO IS wine | D39: BIO Intelligence Service (Nordic wine packaging; via ACE 2020) | E39: 2010 | F39: Nordic countries | G39: Europe | H39: Wine | I39: Beverage | J39: 1 L (0.75 L packs) | K39: PET bottle 0.75 L | L39: Glass one-way 0.75 L | M39: 351 | N39: 1173 | O39: =N39/M39 -> 3.3418803 | P39: =LN(O39) -> 1.2065336 | Q39: g CO2e/L | R39: Second-hand, checked against ACE 2020 Tables 2-3 (ref 12) | S39: second-hand table | T39: packaging only | U39: per volume | V39: no | W39: Commissioned by Nordic alcohol retailers (not a material maker) | X39: Other/unclear | AB39: Glass | AC39: core | AF39: Wohner & Tacker 2020 (Circular Analytics for ACE) Tables 1-4; https://www.tetrapak.com/content/dam/tetrapak/publicweb/gb/en/sustainability/20-011-Circular-Analytics_ACE-Full-report_2021-01-25.pdf
A40: P39 | B40: S19 | C40: BIO IS wine | D40: BIO Intelligence Service (Nordic wine packaging; via ACE 2020) | E40: 2010 | F40: Nordic countries | G40: Europe | H40: Wine | I40: Beverage | J40: 1 L (0.75 L packs) | K40: PET bottle 0.75 L | L40: Beverage carton | M40: 351 | N40: 139 | O40: =N40/M40 -> 0.3960114 | P40: =LN(O40) -> -0.92631229 | Q40: g CO2e/L | R40: Second-hand, checked against ACE 2020 Tables 1-2 | S40: second-hand table | T40: packaging only | U40: per volume | V40: no | W40: Commissioned by Nordic alcohol retailers (not a material maker) | X40: Other/unclear | AB40: Carton | AC40: core | AF40: Wohner & Tacker 2020 (Circular Analytics for ACE) Tables 1-4; https://www.tetrapak.com/content/dam/tetrapak/publicweb/gb/en/sustainability/20-011-Circular-Analytics_ACE-Full-report_2021-01-25.pdf
...

Sheet S2b_Study_means
A1: group | B1: study_id | C1: study_mean_ln_ratio | D1: n_pairs | E1: n_pairs_alt_better
A2: Core pool (all classes) | B2: S1 | C2: =AVERAGEIFS(S1_Extracted_pairs!$P$2:$P$47,S1_Extracted_pairs!$AC$2:$AC$47,"core",S1_Extracted_pairs!$B$2:$B$47,B2) -> 0.78322613 | D2: =COUNTIFS(S1_Extracted_pairs!$AC$2:$AC$47,"core",S1_Extracted_pairs!$B$2:$B$47,B2) -> 3 | E2: =COUNTIFS(S1_Extracted_pairs!$AC$2:$AC$47,"core",S1_Extracted_pairs!$B$2:$B$47,B2,S1_Extracted_pairs!$O$2:$O$47,"<1") -> 1
A3: Core pool (all classes) | B3: S2 | C3: =AVERAGEIFS(S1_Extracted_pairs!$P$2:$P$47,S1_Extracted_pairs!$AC$2:$AC$47,"core",S1_Extracted_pairs!$B$2:$B$47,B3) -> 0.56703818 | D3: =COUNTIFS(S1_Extracted_pairs!$AC$2:$AC$47,"core",S1_Extracted_pairs!$B$2:$B$47,B3) -> 1 | E3: =COUNTIFS(S1_Extracted_pairs!$AC$2:$AC$47,"core",S1_Extracted_pairs!$B$2:$B$47,B3,S1_Extracted_pairs!$O$2:$O$47,"<1") -> 0
A4: Core pool (all classes) | B4: S3 | C4: =AVERAGEIFS(S1_Extracted_pairs!$P$2:$P$47,S1_Extracted_pairs!$AC$2:$AC$47,"core",S1_Extracted_pairs!$B$2:$B$47,B4) -> 1.3470736 | D4: =COUNTIFS(S1_Extracted_pairs!$AC$2:$AC$47,"core",S1_Extracted_pairs!$B$2:$B$47,B4) -> 1 | E4: =COUNTIFS(S1_Extracted_pairs!$AC$2:$AC$47,"core",S1_Extracted_pairs!$B$2:$B$47,B4,S1_Extracted_pairs!$O$2:$O$47,"<1") -> 0
A5: Core pool (all classes) | B5: S4 | C5: =AVERAGEIFS(S1_Extracted_pairs!$P$2:$P$47,S1_Extracted_pairs!$AC$2:$AC$47,"core",S1_Extracted_pairs!$B$2:$B$47,B5) -> 1.652252 | D5: =COUNTIFS(S1_Extracted_pairs!$AC$2:$AC$47,"core",S1_Extracted_pairs!$B$2:$B$47,B5) -> 1 | E5: =COUNTIFS(S1_Extracted_pairs!$AC$2:$AC$47,"core",S1_Extracted_pairs!$B$2:$B$47,B5,S1_Extracted_pairs!$O$2:$O$47,"<1") -> 0
A6: Core pool (all classes) | B6: S5 | C6: =AVERAGEIFS(S1_Extracted_pairs!$P$2:$P$47,S1_Extracted_pairs!$AC$2:$AC$47,"core",S1_Extracted_pairs!$B$2:$B$47,B6) -> -0.5065762 | D6: =COUNTIFS(S1_Extracted_pairs!$AC$2:$AC$47,"core",S1_Extracted_pairs!$B$2:$B$47,B6) -> 2 | E6: =COUNTIFS(S1_Extracted_pairs!$AC$2:$AC$47,"core",S1_Extracted_pairs!$B$2:$B$47,B6,S1_Extracted_pairs!$O$2:$O$47,"<1") -> 2
A7: Core pool (all classes) | B7: S8 | C7: =AVERAGEIFS(S1_Extracted_pairs!$P$2:$P$47,S1_Extracted_pairs!$AC$2:$AC$47,"core",S1_Extracted_pairs!$B$2:$B$47,B7) -> 0.47491497 | D7: =COUNTIFS(S1_Extracted_pairs!$AC$2:$AC$47,"core",S1_Extracted_pairs!$B$2:$B$47,B7) -> 2 | E7: =COUNTIFS(S1_Extracted_pairs!$AC$2:$AC$47,"core",S1_Extracted_pairs!$B$2:$B$47,B7,S1_Extracted_pairs!$O$2:$O$47,"<1") -> 0
A8: Core pool (all classes) | B8: S10 | C8: =AVERAGEIFS(S1_Extracted_pairs!$P$2:$P$47,S1_Extracted_pairs!$AC$2:$AC$47,"core",S1_Extracted_pairs!$B$2:$B$47,B8) -> 0.68225943 | D8: =COUNTIFS(S1_Extracted_pairs!$AC$2:$AC$47,"core",S1_Extracted_pairs!$B$2:$B$47,B8) -> 4 | E8: =COUNTIFS(S1_Extracted_pairs!$AC$2:$AC$47,"core",S1_Extracted_pairs!$B$2:$B$47,B8,S1_Extracted_pairs!$O$2:$O$47,"<1") -> 0
A9: Core pool (all classes) | B9: S13 | C9: =AVERAGEIFS(S1_Extracted_pairs!$P$2:$P$47,S1_Extracted_pairs!$AC$2:$AC$47,"core",S1_Extracted_pairs!$B$2:$B$47,B9) -> -0.066917883 | D9: =COUNTIFS(S1_Extracted_pairs!$AC$2:$AC$47,"core",S1_Extracted_pairs!$B$2:$B$47,B9) -> 2 | E9: =COUNTIFS(S1_Extracted_pairs!$AC$2:$AC$47,"core",S1_Extracted_pairs!$B$2:$B$47,B9,S1_Extracted_pairs!$O$2:$O$47,"<1") -> 1
A10: Core pool (all classes) | B10: S14 | C10: =AVERAGEIFS(S1_Extracted_pairs!$P$2:$P$47,S1_Extracted_pairs!$AC$2:$AC$47,"core",S1_Extracted_pairs!$B$2:$B$47,B10) -> 0.35316583 | D10: =COUNTIFS(S1_Extracted_pairs!$AC$2:$AC$47,"core",S1_Extracted_pairs!$B$2:$B$47,B10) -> 5 | E10: =COUNTIFS(S1_Extracted_pairs!$AC$2:$AC$47,"core",S1_Extracted_pairs!$B$2:$B$47,B10,S1_Extracted_pairs!$O$2:$O$47,"<1") -> 3
A11: Core pool (all classes) | B11: S15 | C11: =AVERAGEIFS(S1_Extracted_pairs!$P$2:$P$47,S1_Extracted_pairs!$AC$2:$AC$47,"core",S1_Extracted_pairs!$B$2:$B$47,B11) -> 0.45142724 | D11: =COUNTIFS(S1_Extracted_pairs!$AC$2:$AC$47,"core",S1_Extracted_pairs!$B$2:$B$47,B11) -> 1 | E11: =COUNTIFS(S1_Extracted_pairs!$AC$2:$AC$47,"core",S1_Extracted_pairs!$B$2:$B$47,B11,S1_Extracted_pairs!$O$2:$O$47,"<1") -> 0
A12: Core pool (all classes) | B12: S17 | C12: =AVERAGEIFS(S1_Extracted_pairs!$P$2:$P$47,S1_Extracted_pairs!$AC$2:$AC$47,"core",S1_Extracted_pairs!$B$2:$B$47,B12) -> -0.19336943 | D12: =COUNTIFS(S1_Extracted_pairs!$AC$2:$AC$47,"core",S1_Extracted_pairs!$B$2:$B$47,B12) -> 2 | E12: =COUNTIFS(S1_Extracted_pairs!$AC$2:$AC$47,"core",S1_Extracted_pairs!$B$2:$B$47,B12,S1_Extracted_pairs!$O$2:$O$47,"<1") -> 1
A13: Core pool (all classes) | B13: S18 | C13: =AVERAGEIFS(S1_Extracted_pairs!$P$2:$P$47,S1_Extracted_pairs!$AC$2:$AC$47,"core",S1_Extracted_pairs!$B$2:$B$47,B13) -> -0.46155457 | D13: =COUNTIFS(S1_Extracted_pairs!$AC$2:$AC$47,"core",S1_Extracted_pairs!$B$2:$B$47,B13) -> 1 | E13: =COUNTIFS(S1_Extracted_pairs!$AC$2:$AC$47,"core",S1_Extracted_pairs!$B$2:$B$47,B13,S1_Extracted_pairs!$O$2:$O$47,"<1") -> 1
... A17: Core pool (all classes) | B17: S7 | C17: =AVERAGEIFS(S1_Extracted_pairs!$P$2:$P$47,S1_Extracted_pairs!$AC$2:$AC$47,"core",S1_Extracted_pairs!$B$2:$B$47,B17) -> -0.32930375 | D17: =COUNTIFS(S1_Extracted_pairs!$AC$2:$AC$47,"core",S1_Extracted_pairs!$B$2:$B$47,B17) -> 1 | E17: =COUNTIFS(S1_Extracted_pairs!$AC$2:$AC$47,"core",S1_Extracted_pairs!$B$2:$B$47,B17,S1_Extracted_pairs!$O$2:$O$47,"<1") -> 1
A18: Glass vs plastic | B18: S1 | C18: =AVERAGEIFS(S1_Extracted_pairs!$P$2:$P$47,S1_Extracted_pairs!$AC$2:$AC$47,"core",S1_Extracted_pairs!$B$2:$B$47,B18,S1_Extracted_pairs!$AB$2:$AB$47,"Glass") -> 1.5501382 | D18: =COUNTIFS(S1_Extracted_pairs!$AC$2:$AC$47,"core",S1_Extracted_pairs!$B$2:$B$47,B18,S1_Extracted_pairs!$AB$2:$AB$47,"Glass") -> 1 | E18: =COUNTIFS(S1_Extracted_pairs!$AC$2:$AC$47,"core",S1_Extracted_pairs!$B$2:$B$47,B18,S1_Extracted_pairs!$AB$2:$AB$47,"Glass",S1_Extracted_pairs!$O$2:$O$47,"<1") -> 0
A19: Glass vs plastic | B19: S2 | C19: =AVERAGEIFS(S1_Extracted_pairs!$P$2:$P$47,S1_Extracted_pairs!$AC$2:$AC$47,"core",S1_Extracted_pairs!$B$2:$B$47,B19,S1_Extracted_pairs!$AB$2:$AB$47,"Glass") -> 0.56703818 | D19: =COUNTIFS(S1_Extracted_pairs!$AC$2:$AC$47,"core",S1_Extracted_pairs!$B$2:$B$47,B19,S1_Extracted_pairs!$AB$2:$AB$47,"Glass") -> 1 | E19: =COUNTIFS(S1_Extracted_pairs!$AC$2:$AC$47,"core",S1_Extracted_pairs!$B$2:$B$47,B19,S1_Extracted_pairs!$AB$2:$AB$47,"Glass",S1_Extracted_pairs!$O$2:$O$47,"<1") -> 0
A20: Glass vs plastic | B20: S4 | C20: =AVERAGEIFS(S1_Extracted_pairs!$P$2:$P$47,S1_Extracted_pairs!$AC$2:$AC$47,"core",S1_Extracted_pairs!$B$2:$B$47,B20,S1_Extracted_pairs!$AB$2:$AB$47,"Glass") -> 1.652252 | D20: =COUNTIFS(S1_Extracted_pairs!$AC$2:$AC$47,"core",S1_Extracted_pairs!$B$2:$B$47,B20,S1_Extracted_pairs!$AB$2:$AB$47,"Glass") -> 1 | E20: =COUNTIFS(S1_Extracted_pairs!$AC$2:$AC$47,"core",S1_Extracted_pairs!$B$2:$B$47,B20,S1_Extracted_pairs!$AB$2:$AB$47,"Glass",S1_Extracted_pairs!$O$2:$O$47,"<1") -> 0
A21: Glass vs plastic | B21: S8 | C21: =AVERAGEIFS(S1_Extracted_pairs!$P$2:$P$47,S1_Extracted_pairs!$AC$2:$AC$47,"core",S1_Extracted_pairs!$B$2:$B$47,B21,S1_Extracted_pairs!$AB$2:$AB$47,"Glass") -> 0.83803853 | D21: =COUNTIFS(S1_Extracted_pairs!$AC$2:$AC$47,"core",S1_Extracted_pairs!$B$2:$B$47,B21,S1_Extracted_pairs!$AB$2:$AB$47,"Glass") -> 1 | E21: =COUNTIFS(S1_Extracted_pairs!$AC$2:$AC$47,"core",S1_Extracted_pairs!$B$2:$B$47,B21,S1_Extracted_pairs!$AB$2:$AB$47,"Glass",S1_Extracted_pairs!$O$2:$O$47,"<1") -> 0
A22: Glass vs plastic | B22: S10 | C22: =AVERAGEIFS(S1_Extracted_pairs!$P$2:$P$47,S1_Extracted_pairs!$AC$2:$AC$47,"core",S1_Extracted_pairs!$B$2:$B$47,B22,S1_Extracted_pairs!$AB$2:$AB$47,"Glass") -> 0.97024189 | D22: =COUNTIFS(S1_Extracted_pairs!$AC$2:$AC$47,"core",S1_Extracted_pairs!$B$2:$B$47,B22,S1_Extracted_pairs!$AB$2:$AB$47,"Glass") -> 2 | E22: =COUNTIFS(S1_Extracted_pairs!$AC$2:$AC$47,"core",S1_Extracted_pairs!$B$2:$B$47,B22,S1_Extracted_pairs!$AB$2:$AB$47,"Glass",S1_Extracted_pairs!$O$2:$O$47,"<1") -> 0
A23: Glass vs plastic | B23: S14 | C23: =AVERAGEIFS(S1_Extracted_pairs!$P$2:$P$47,S1_Extracted_pairs!$AC$2:$AC$47,"core",S1_Extracted_pairs!$B$2:$B$47,B23,S1_Extracted_pairs!$AB$2:$AB$47,"Glass") -> 1.141529 | D23: =COUNTIFS(S1_Extracted_pairs!$AC$2:$AC$47,"core",S1_Extracted_pairs!$B$2:$B$47,B23,S1_Extracted_pairs!$AB$2:$AB$47,"Glass") -> 2 | E23: =COUNTIFS(S1_Extracted_pairs!$AC$2:$AC$47,"core",S1_Extracted_pairs!$B$2:$B$47,B23,S1_Extracted_pairs!$AB$2:$AB$47,"Glass",S1_Extracted_pairs!$O$2:$O$47,"<1") -> 0
A24: Glass vs plastic | B24: S15 | C24: =AVERAGEIFS(S1_Extracted_pairs!$P$2:$P$47,S1_Extracted_pairs!$AC$2:$AC$47,"core",S1_Extracted_pairs!$B$2:$B$47,B24,S1_Extracted_pairs!$AB$2:$AB$47,"Glass") -> 0.45142724 | D24: =COUNTIFS(S1_Extracted_pairs!$AC$2:$AC$47,"core",S1_Extracted_pairs!$B$2:$B$47,B24,S1_Extracted_pairs!$AB$2:$AB$47,"Glass") -> 1 | E24: =COUNTIFS(S1_Extracted_pairs!$AC$2:$AC$47,"core",S1_Extracted_pairs!$B$2:$B$47,B24,S1_Extracted_pairs!$AB$2:$AB$47,"Glass",S1_Extracted_pairs!$O$2:$O$47,"<1") -> 0
A25: Glass vs plastic | B25: S17 | C25: =AVERAGEIFS(S1_Extracted_pairs!$P$2:$P$47,S1_Extracted_pairs!$AC$2:$AC$47,"core",S1_Extracted_pairs!$B$2:$B$47,B25,S1_Extracted_pairs!$AB$2:$AB$47,"Glass") -> 0.15320416 | D25: =COUNTIFS(S1_Extracted_pairs!$AC$2:$AC$47,"core",S1_Extracted_pairs!$B$2:$B$47,B25,S1_Extracted_pairs!$AB$2:$AB$47,"Glass") -> 1 | E25: =COUNTIFS(S1_Extracted_pairs!$AC$2:$AC$47,"core",S1_Extracted_pairs!$B$2:$B$47,B25,S1_Extracted_pairs!$AB$2:$AB$47,"Glass",S1_Extracted_pairs!$O$2:$O$47,"<1") -> 0
A26: Glass vs plastic | B26: S19 | C26: =AVERAGEIFS(S1_Extracted_pairs!$P$2:$P$47,S1_Extracted_pairs!$AC$2:$AC$47,"core",S1_Extracted_pairs!$B$2:$B$47,B26,S1_Extracted_pairs!$AB$2:$AB$47,"Glass") -> 1.2065336 | D26: =COUNTIFS(S1_Extracted_pairs!$AC$2:$AC$47,"core",S1_Extracted_pairs!$B$2:$B$47,B26,S1_Extracted_pairs!$AB$2:$AB$47,"Glass") -> 1 | E26: =COUNTIFS(S1_Extracted_pairs!$AC$2:$AC$47,"core",S1_Extracted_pairs!$B$2:$B$47,B26,S1_Extracted_pairs!$AB$2:$AB$47,"Glass",S1_Extracted_pairs!$O$2:$O$47,"<1") -> 0
A27: Reusable glass vs plastic | B27: S8 | C27: =AVERAGEIFS(S1_Extracted_pairs!$P$2:$P$47,S1_Extracted_pairs!$AC$2:$AC$47,"core",S1_Extracted_pairs!$B$2:$B$47,B27,S1_Extracted_pairs!$AB$2:$AB$47,"Reusable glass") -> 0.11179141 | D27: =COUNTIFS(S1_Extracted_pairs!$AC$2:$AC$47,"core",S1_Extracted_pairs!$B$2:$B$47,B27,S1_Extracted_pairs!$AB$2:$AB$47,"Reusable glass") -> 1 | E27: =COUNTIFS(S1_Extracted_pairs!$AC$2:$AC$47,"core",S1_Extracted_pairs!$B$2:$B$47,B27,S1_Extracted_pairs!$AB$2:$AB$47,"Reusable glass",S1_Extracted_pairs!$O$2:$O$47,"<1") -> 0
A28: Reusable glass vs plastic | B28: S13 | C28: =AVERAGEIFS(S1_Extracted_pairs!$P$2:$P$47,S1_Extracted_pairs!$AC$2:$AC$47,"core",S1_Extracted_pairs!$B$2:$B$47,B28,S1_Extracted_pairs!$AB$2:$AB$47,"Reusable glass") -> -0.066917883 | D28: =COUNTIFS(S1_Extracted_pairs!$AC$2:$AC$47,"core",S1_Extracted_pairs!$B$2:$B$47,B28,S1_Extracted_pairs!$AB$2:$AB$47,"Reusable glass") -> 2 | E28: =COUNTIFS(S1_Extracted_pairs!$AC$2:$AC$47,"core",S1_Extracted_pairs!$B$2:$B$47,B28,S1_Extracted_pairs!$AB$2:$AB$47,"Reusable glass",S1_Extracted_pairs!$O$2:$O$47,"<1") -> 1
A29: Reusable glass vs plastic | B29: S14 | C29: =AVERAGEIFS(S1_Extracted_pairs!$P$2:$P$47,S1_Extracted_pairs!$AC$2:$AC$47,"core",S1_Extracted_pairs!$B$2:$B$47,B29,S1_Extracted_pairs!$AB$2:$AB$47,"Reusable glass") -> -0.086947808 | D29: =COUNTIFS(S1_Extracted_pairs!$AC$2:$AC$47,"core",S1_Extracted_pairs!$B$2:$B$47,B29,S1_Extracted_pairs!$AB$2:$AB$47,"Reusable glass") -> 2 | E29: =COUNTIFS(S1_Extracted_pairs!$AC$2:$AC$47,"core",S1_Extracted_pairs!$B$2:$B$47,B29,S1_Extracted_pairs!$AB$2:$AB$47,"Reusable glass",S1_Extracted_pairs!$O$2:$O$47,"<1") -> 2
A30: Reusable glass vs plastic | B30: S7 | C30: =AVERAGEIFS(S1_Extracted_pairs!$P$2:$P$47,S1_Extracted_pairs!$AC$2:$AC$47,"core",S1_Extracted_pairs!$B$2:$B$47,B30,S1_Extracted_pairs!$AB$2:$AB$47,"Reusable glass") -> -0.32930375 | D30: =COUNTIFS(S1_Extracted_pairs!$AC$2:$AC$47,"core",S1_Extracted_pairs!$B$2:$B$47,B30,S1_Extracted_pairs!$AB$2:$AB$47,"Reusable glass") -> 1 | E30: =COUNTIFS(S1_Extracted_pairs!$AC$2:$AC$47,"core",S1_Extracted_pairs!$B$2:$B$47,B30,S1_Extracted_pairs!$AB$2:$AB$47,"Reusable glass",S1_Extracted_pairs!$O$2:$O$47,"<1") -> 1
A31: Aluminium vs plastic | B31: S1 | C31: =AVERAGEIFS(S1_Extracted_pairs!$P$2:$P$47,S1_Extracted_pairs!$AC$2:$AC$47,"core",S1_Extracted_pairs!$B$2:$B$47,B31,S1_Extracted_pairs!$AB$2:$AB$47,"Aluminium") -> 0.95200881 | D31: =COUNTIFS(S1_Extracted_pairs!$AC$2:$AC$47,"core",S1_Extracted_pairs!$B$2:$B$47,B31,S1_Extracted_pairs!$AB$2:$AB$47,"Aluminium") -> 1 | E31: =COUNTIFS(S1_Extracted_pairs!$AC$2:$AC$47,"core",S1_Extracted_pairs!$B$2:$B$47,B31,S1_Extracted_pairs!$AB$2:$AB$47,"Aluminium",S1_Extracted_pairs!$O$2:$O$47,"<1") -> 0
A32: Aluminium vs plastic | B32: S3 | C32: =AVERAGEIFS(S1_Extracted_pairs!$P$2:$P$47,S1_Extracted_pairs!$AC$2:$AC$47,"core",S1_Extracted_pairs!$B$2:$B$47,B32,S1_Extracted_pairs!$AB$2:$AB$47,"Aluminium") -> 1.3470736 | D32: =COUNTIFS(S1_Extracted_pairs!$AC$2:$AC$47,"core",S1_Extracted_pairs!$B$2:$B$47,B32,S1_Extracted_pairs!$AB$2:$AB$47,"Aluminium") -> 1 | E32: =COUNTIFS(S1_Extracted_pairs!$AC$2:$AC$47,"core",S1_Extracted_pairs!$B$2:$B$47,B32,S1_Extracted_pairs!$AB$2:$AB$47,"Aluminium",S1_Extracted_pairs!$O$2:$O$47,"<1") -> 0
A33: Aluminium vs plastic | B33: S10 | C33: =AVERAGEIFS(S1_Extracted_pairs!$P$2:$P$47,S1_Extracted_pairs!$AC$2:$AC$47,"core",S1_Extracted_pairs!$B$2:$B$47,B33,S1_Extracted_pairs!$AB$2:$AB$47,"Aluminium") -> 0.39427696 | D33: =COUNTIFS(S1_Extracted_pairs!$AC$2:$AC$47,"core",S1_Extracted_pairs!$B$2:$B$47,B33,S1_Extracted_pairs!$AB$2:$AB$47,"Aluminium") -> 2 | E33: =COUNTIFS(S1_Extracted_pairs!$AC$2:$AC$47,"core",S1_Extracted_pairs!$B$2:$B$47,B33,S1_Extracted_pairs!$AB$2:$AB$47,"Aluminium",S1_Extracted_pairs!$O$2:$O$47,"<1") -> 0
A34: Carton vs plastic | B34: S1 | C34: =AVERAGEIFS(S1_Extracted_pairs!$P$2:$P$47,S1_Extracted_pairs!$AC$2:$AC$47,"core",S1_Extracted_pairs!$B$2:$B$47,B34,S1_Extracted_pairs!$AB$2:$AB$47,"Carton") -> -0.15246859 | D34: =COUNTIFS(S1_Extracted_pairs!$AC$2:$AC$47,"core",S1_Extracted_pairs!$B$2:$B$47,B34,S1_Extracted_pairs!$AB$2:$AB$47,"Carton") -> 1 | E34: =COUNTIFS(S1_Extracted_pairs!$AC$2:$AC$47,"core",S1_Extracted_pairs!$B$2:$B$47,B34,S1_Extracted_pairs!$AB$2:$AB$47,"Carton",S1_Extracted_pairs!$O$2:$O$47,"<1") -> 1
A35: Carton vs plastic | B35: S5 | C35: =AVERAGEIFS(S1_Extracted_pairs!$P$2:$P$47,S1_Extracted_pairs!$AC$2:$AC$47,"core",S1_Extracted_pairs!$B$2:$B$47,B35,S1_Extracted_pairs!$AB$2:$AB$47,"Carton") -> -0.5065762 | D35: =COUNTIFS(S1_Extracted_pairs!$AC$2:$AC$47,"core",S1_Extracted_pairs!$B$2:$B$47,B35,S1_Extracted_pairs!$AB$2:$AB$47,"Carton") -> 2 | E35: =COUNTIFS(S1_Extracted_pairs!$AC$2:$AC$47,"core",S1_Extracted_pairs!$B$2:$B$47,B35,S1_Extracted_pairs!$AB$2:$AB$47,"Carton",S1_Extracted_pairs!$O$2:$O$47,"<1") -> 2
A36: Carton vs plastic | B36: S14 | C36: =AVERAGEIFS(S1_Extracted_pairs!$P$2:$P$47,S1_Extracted_pairs!$AC$2:$AC$47,"core",S1_Extracted_pairs!$B$2:$B$47,B36,S1_Extracted_pairs!$AB$2:$AB$47,"Carton") -> -0.34333333 | D36: =COUNTIFS(S1_Extracted_pairs!$AC$2:$AC$47,"core",S1_Extracted_pairs!$B$2:$B$47,B36,S1_Extracted_pairs!$AB$2:$AB$47,"Carton") -> 1 | E36: =COUNTIFS(S1_Extracted_pairs!$AC$2:$AC$47,"core",S1_Extracted_pairs!$B$2:$B$47,B36,S1_Extracted_pairs!$AB$2:$AB$47,"Carton",S1_Extracted_pairs!$O$2:$O$47,"<1") -> 1
A37: Carton vs plastic | B37: S17 | C37: =AVERAGEIFS(S1_Extracted_pairs!$P$2:$P$47,S1_Extracted_pairs!$AC$2:$AC$47,"core",S1_Extracted_pairs!$B$2:$B$47,B37,S1_Extracted_pairs!$AB$2:$AB$47,"Carton") -> -0.53994302 | D37: =COUNTIFS(S1_Extracted_pairs!$AC$2:$AC$47,"core",S1_Extracted_pairs!$B$2:$B$47,B37,S1_Extracted_pairs!$AB$2:$AB$47,"Carton") -> 1 | E37: =COUNTIFS(S1_Extracted_pairs!$AC$2:$AC$47,"core",S1_Extracted_pairs!$B$2:$B$47,B37,S1_Extracted_pairs!$AB$2:$AB$47,"Carton",S1_Extracted_pairs!$O$2:$O$47,"<1") -> 1
A38: Carton vs plastic | B38: S18 | C38: =AVERAGEIFS(S1_Extracted_pairs!$P$2:$P$47,S1_Extracted_pairs!$AC$2:$AC$47,"core",S1_Extracted_pairs!$B$2:$B$47,B38,S1_Extracted_pairs!$AB$2:$AB$47,"Carton") -> -0.46155457 | D38: =COUNTIFS(S1_Extracted_pairs!$AC$2:$AC$47,"core",S1_Extracted_pairs!$B$2:$B$47,B38,S1_Extracted_pairs!$AB$2:$AB$47,"Carton") -> 1 | E38: =COUNTIFS(S1_Extracted_pairs!$AC$2:$AC$47,"core",S1_Extracted_pairs!$B$2:$B$47,B38,S1_Extracted_pairs!$AB$2:$AB$47,"Carton",S1_Extracted_pairs!$O$2:$O$47,"<1") -> 1
A39: Carton vs plastic | B39: S19 | C39: =AVERAGEIFS(S1_Extracted_pairs!$P$2:$P$47,S1_Extracted_pairs!$AC$2:$AC$47,"core",S1_Extracted_pairs!$B$2:$B$47,B39,S1_Extracted_pairs!$AB$2:$AB$47,"Carton") -> -0.92631229 | D39: =COUNTIFS(S1_Extracted_pairs!$AC$2:$AC$47,"core",S1_Extracted_pairs!$B$2:$B$47,B39,S1_Extracted_pairs!$AB$2:$AB$47,"Carton") -> 1 | E39: =COUNTIFS(S1_Extracted_pairs!$AC$2:$AC$47,"core",S1_Extracted_pairs!$B$2:$B$47,B39,S1_Extracted_pairs!$AB$2:$AB$47,"Carton",S1_Extracted_pairs!$O$2:$O$47,"<1") -> 1
A40: Carton vs plastic | B40: S20 | C40: =AVERAGEIFS(S1_Extracted_pairs!$P$2:$P$47,S1_Extracted_pairs!$AC$2:$AC$47,"core",S1_Extracted_pairs!$B$2:$B$47,B40,S1_Extracted_pairs!$AB$2:$AB$47,"Carton") -> -0.33521508 | D40: =COUNTIFS(S1_Extracted_pairs!$AC$2:$AC$47,"core",S1_Extracted_pairs!$B$2:$B$47,B40,S1_Extracted_pairs!$AB$2:$AB$47,"Carton") -> 2 | E40: =COUNTIFS(S1_Extracted_pairs!$AC$2:$AC$47,"core",S1_Extracted_pairs!$B$2:$B$47,B40,S1_Extracted_pairs!$AB$2:$AB$47,"Carton",S1_Extracted_pairs!$O$2:$O$47,"<1") -> 2
A41: Pouch/refill vs plastic | B41: S21 | C41: =AVERAGEIFS(S1_Extracted_pairs!$P$2:$P$47,S1_Extracted_pairs!$AC$2:$AC$47,"core",S1_Extracted_pairs!$B$2:$B$47,B41,S1_Extracted_pairs!$AB$2:$AB$47,"Pouch/refill") -> 0.53841358 | D41: =COUNTIFS(S1_Extracted_pairs!$AC$2:$AC$47,"core",S1_Extracted_pairs!$B$2:$B$47,B41,S1_Extracted_pairs!$AB$2:$AB$47,"Pouch/refill") -> 1 | E41: =COUNTIFS(S1_Extracted_pairs!$AC$2:$AC$47,"core",S1_Extracted_pairs!$B$2:$B$47,B41,S1_Extracted_pairs!$AB$2:$AB$47,"Pouch/refill",S1_Extracted_pairs!$O$2:$O$47,"<1") -> 0

Sheet S2_Meta_analysis
A1: Top: Python results (bootstrap = study-level resampling, 20,000 draws). Bottom: live formula version (t-interval) that recalculates from S1 via S2b.
A3: group | B3: k_studies | C3: n_pairs | D3: mean_ln | E3: ratio | F3: pct_pairs_alt_better | G3: boot_low | H3: boot_high | I3: t_low | J3: t_high | K3: tau_ln | L3: pred_low | M3: pred_high
A4: Core pool (all classes) | B4: 16 | C4: 31 | D4: 0.31855905 | E4: 1.3751448 | F4: 41.935484 | G4: 1.0295334 | H4: 1.8782568 | I4: 0.98400917 | J4: 1.9217537 | K4: 0.62807795 | L4: 0.34598554 | M4: 5.4656136
A5: Glass vs plastic | B5: 9 | C5: 11 | D5: 0.94782254 | E5: 2.5800855 | F5: 0 | G5: 1.8864457 | H5: 3.494365 | I5: 1.7569867 | J5: 3.7887829 | K5: 0.49985463 | L5: 0.76552378 | M5: 8.6957994
A6: Reusable glass vs plastic | B6: 4 | C6: 6 | D6: -0.092844508 | E6: 0.91133519 | F6: 66.666667 | G6: 0.76819837 | H6: 1.0640758 | I6: 0.68306346 | J6: 1.2158926 | K6: 0.18119583 | L6: 0.4782822 | M6: 1.7364891
A7: Aluminium vs plastic | B7: 3 | C7: 4 | D7: 0.89778648 | E7: 2.4541647 | F7: 0 | G7: 1.4833113 | H7: 3.8461538 | I7: 0.7472259 | J7: 8.0603798 | K7: 0.47870704 | L7: 0.22750981 | M7: 26.473252
A8: Carton vs plastic | B8: 7 | C8: 9 | D8: -0.46648615 | E8: 0.62720229 | F8: 100 | G8: 0.52434767 | H8: 0.73069291 | I8: 0.50173184 | J8: 0.78404973 | K8: 0.24134114 | L8: 0.33360404 | M8: 1.1791905
A9: Pouch/refill vs plastic | B9: 1 | C9: 1 | D9: 0.53841358 | E9: 1.7132867 | F9: 0
A11: LIVE FORMULA VERSION (recalculates from S1)
A12: group | B12: k_studies | C12: n_pairs | D12: mean_ln | E12: ratio | F12: t_ci_low | G12: t_ci_high | H12: pct_pairs_alt_better | I12: between_study_SD_ln
A13: Core pool (all classes) | B13: =COUNTIF(S2b_Study_means!$A$2:$A$41,A13) -> 16 | C13: =SUMIF(S2b_Study_means!$A$2:$A$41,A13,S2b_Study_means!$D$2:$D$41) -> 31 | D13: =AVERAGEIF(S2b_Study_means!$A$2:$A$41,A13,S2b_Study_means!$C$2:$C$41) -> 0.31855905 | E13: =EXP(D13) -> 1.3751448 | F13: =IF(B13>1,EXP(D13-TINV(0.05,B13-1)*I13/SQRT(B13)),"n/a") -> 0.98400917 | G13: =IF(B13>1,EXP(D13+TINV(0.05,B13-1)*I13/SQRT(B13)),"n/a") -> 1.9217537 | H13: =100*SUMIF(S2b_Study_means!$A$2:$A$41,A13,S2b_Study_means!$E$2:$E$41)/C13 -> 41.935484 | I13: =IF(B13>1,SQRT((SUMPRODUCT((S2b_Study_means!$A$2:$A$41=A13)*(S2b_Study_means!$C$2:$C$41^2))-B13*D13^2)/(B13-1)),"n/a") -> 0.62807795
A14: Glass vs plastic | B14: =COUNTIF(S2b_Study_means!$A$2:$A$41,A14) -> 9 | C14: =SUMIF(S2b_Study_means!$A$2:$A$41,A14,S2b_Study_means!$D$2:$D$41) -> 11 | D14: =AVERAGEIF(S2b_Study_means!$A$2:$A$41,A14,S2b_Study_means!$C$2:$C$41) -> 0.94782254 | E14: =EXP(D14) -> 2.5800855 | F14: =IF(B14>1,EXP(D14-TINV(0.05,B14-1)*I14/SQRT(B14)),"n/a") -> 1.7569867 | G14: =IF(B14>1,EXP(D14+TINV(0.05,B14-1)*I14/SQRT(B14)),"n/a") -> 3.7887829 | H14: =100*SUMIF(S2b_Study_means!$A$2:$A$41,A14,S2b_Study_means!$E$2:$E$41)/C14 -> 0 | I14: =IF(B14>1,SQRT((SUMPRODUCT((S2b_Study_means!$A$2:$A$41=A14)*(S2b_Study_means!$C$2:$C$41^2))-B14*D14^2)/(B14-1)),"n/a") -> 0.49985463
A15: Reusable glass vs plastic | B15: =COUNTIF(S2b_Study_means!$A$2:$A$41,A15) -> 4 | C15: =SUMIF(S2b_Study_means!$A$2:$A$41,A15,S2b_Study_means!$D$2:$D$41) -> 6 | D15: =AVERAGEIF(S2b_Study_means!$A$2:$A$41,A15,S2b_Study_means!$C$2:$C$41) -> -0.092844508 | E15: =EXP(D15) -> 0.91133519 | F15: =IF(B15>1,EXP(D15-TINV(0.05,B15-1)*I15/SQRT(B15)),"n/a") -> 0.68306346 | G15: =IF(B15>1,EXP(D15+TINV(0.05,B15-1)*I15/SQRT(B15)),"n/a") -> 1.2158926 | H15: =100*SUMIF(S2b_Study_means!$A$2:$A$41,A15,S2b_Study_means!$E$2:$E$41)/C15 -> 66.666667 | I15: =IF(B15>1,SQRT((SUMPRODUCT((S2b_Study_means!$A$2:$A$41=A15)*(S2b_Study_means!$C$2:$C$41^2))-B15*D15^2)/(B15-1)),"n/a") -> 0.18119583
A16: Aluminium vs plastic | B16: =COUNTIF(S2b_Study_means!$A$2:$A$41,A16) -> 3 | C16: =SUMIF(S2b_Study_means!$A$2:$A$41,A16,S2b_Study_means!$D$2:$D$41) -> 4 | D16: =AVERAGEIF(S2b_Study_means!$A$2:$A$41,A16,S2b_Study_means!$C$2:$C$41) -> 0.89778648 | E16: =EXP(D16) -> 2.4541647 | F16: =IF(B16>1,EXP(D16-TINV(0.05,B16-1)*I16/SQRT(B16)),"n/a") -> 0.7472259 | G16: =IF(B16>1,EXP(D16+TINV(0.05,B16-1)*I16/SQRT(B16)),"n/a") -> 8.0603798 | H16: =100*SUMIF(S2b_Study_means!$A$2:$A$41,A16,S2b_Study_means!$E$2:$E$41)/C16 -> 0 | I16: =IF(B16>1,SQRT((SUMPRODUCT((S2b_Study_means!$A$2:$A$41=A16)*(S2b_Study_means!$C$2:$C$41^2))-B16*D16^2)/(B16-1)),"n/a") -> 0.47870704
A17: Carton vs plastic | B17: =COUNTIF(S2b_Study_means!$A$2:$A$41,A17) -> 7 | C17: =SUMIF(S2b_Study_means!$A$2:$A$41,A17,S2b_Study_means!$D$2:$D$41) -> 9 | D17: =AVERAGEIF(S2b_Study_means!$A$2:$A$41,A17,S2b_Study_means!$C$2:$C$41) -> -0.46648615 | E17: =EXP(D17) -> 0.62720229 | F17: =IF(B17>1,EXP(D17-TINV(0.05,B17-1)*I17/SQRT(B17)),"n/a") -> 0.50173184 | G17: =IF(B17>1,EXP(D17+TINV(0.05,B17-1)*I17/SQRT(B17)),"n/a") -> 0.78404973 | H17: =100*SUMIF(S2b_Study_means!$A$2:$A$41,A17,S2b_Study_means!$E$2:$E$41)/C17 -> 100 | I17: =IF(B17>1,SQRT((SUMPRODUCT((S2b_Study_means!$A$2:$A$41=A17)*(S2b_Study_means!$C$2:$C$41^2))-B17*D17^2)/(B17-1)),"n/a") -> 0.24134114
A18: Pouch/refill vs plastic | B18: =COUNTIF(S2b_Study_means!$A$2:$A$41,A18) -> 1 | C18: =SUMIF(S2b_Study_means!$A$2:$A$41,A18,S2b_Study_means!$D$2:$D$41) -> 1 | D18: =AVERAGEIF(S2b_Study_means!$A$2:$A$41,A18,S2b_Study_means!$C$2:$C$41) -> 0.53841358 | E18: =EXP(D18) -> 1.7132867 | F18: =IF(B18>1,EXP(D18-TINV(0.05,B18-1)*I18/SQRT(B18)),"n/a") -> n/a | G18: =IF(B18>1,EXP(D18+TINV(0.05,B18-1)*I18/SQRT(B18)),"n/a") -> n/a | H18: =100*SUMIF(S2b_Study_means!$A$2:$A$41,A18,S2b_Study_means!$E$2:$E$41)/C18 -> 0 | I18: =IF(B18>1,SQRT((SUMPRODUCT((S2b_Study_means!$A$2:$A$41=A18)*(S2b_Study_means!$C$2:$C$41^2))-B18*D18^2)/(B18-1)),"n/a") -> n/a

Sheet S3_Moderators
A1: class_adjusted_shift = how much the ratio moves for studies at 'level' vs all others after removing the material mix (1 = no effect; interval from study bootstrap).
A3: moderator | B3: level | C3: other | D3: k_level | E3: k_other | F3: n_level | G3: n_other | H3: raw_ratio_level | I3: raw_ratio_other | J3: class_adjusted_shift | K3: shift_low | L3: shift_high
A4: Region | B4: Europe | C4: all other | D4: 11 | E4: 5 | F4: 25 | G4: 6 | H4: 1.2432576 | I4: 1.7166451 | J4: 0.76514824 | K4: 0.53921429 | L4: 1.0618643
A5: System boundary | B5: packaging only | C5: all other | D5: 11 | E5: 5 | F5: 20 | G5: 11 | H5: 1.1439217 | I5: 2.0617839 | J5: 0.87080166 | K5: 0.59354427 | L5: 1.2465613
A6: Functional unit | B6: per volume | C6: all other | D6: 14 | E6: 2 | F6: 29 | G6: 2 | H6: 1.2578323 | I6: 2.5670147 | J6: 0.76600652 | K6: 0.55157155 | L6: 1.0643134
A7: Data source | B7: second-hand table | C7: all other | D7: 8 | E7: 8 | F7: 18 | G7: 13 | H7: 1.0391884 | I7: 1.8197117 | J7: 0.74109297 | K7: 0.57040555 | L7: 0.96292205
A8: Funder | B8: Industry-linked | C8: all other | D8: 5 | E8: 11 | F8: 11 | G8: 20 | H8: 1.1116316 | I8: 1.5147563 | J8: 1.140356 | K8: 0.85984196 | L8: 1.5070114
A9: End of life stated in source | B9: yes | C9: all other | D9: 4 | E9: 12 | F9: 8 | G9: 23 | H9: 1.4071566 | I9: 1.3646369 | J9: 0.87658154 | K9: 0.69329203 | L9: 1.1053836

Sheet S4_Sensitivity_LOO
A1: Sensitivity analyses on the core pool, then leave-one-study-out (below).
A3: group | B3: k_studies | C3: n_pairs | D3: mean_ln | E3: ratio | F3: pct_pairs_alt_better | G3: boot_low | H3: boot_high | I3: t_low | J3: t_high | K3: tau_ln | L3: pred_low | M3: pred_high
A4: Core pool (headline) | B4: 16 | C4: 31 | D4: 0.31855905 | E4: 1.3751448 | F4: 41.935484 | G4: 1.0243609 | H4: 1.8769979 | I4: 0.98400917 | J4: 1.9217537 | K4: 0.62807795 | L4: 0.34598554 | M4: 5.4656136
A5: Core + weak pairs (Saleh, Pasqualino, tray, 30 uses) | B5: 20 | C5: 38 | D5: 0.45752172 | E5: 1.5801531 | F5: 39.473684 | G5: 1.1088506 | H5: 2.3875854 | I5: 1.0347844 | J5: 2.4129507 | K5: 0.90452049 | L5: 0.2270889 | M5: 10.995182
A6: Excluding second-hand values | B6: 8 | C6: 13 | D6: 0.59867806 | E6: 1.8197117 | F6: 30.769231 | G6: 1.1600899 | H6: 2.8340377 | I6: 1.0171402 | J6: 3.2555497 | K6: 0.69577574 | L6: 0.31778788 | M6: 10.420003
A7: Second-hand values only | B7: 8 | C7: 18 | D7: 0.038440042 | E7: 1.0391884 | F7: 50 | G7: 0.79273258 | H7: 1.3791014 | I7: 0.72754199 | J7: 1.4843302 | K7: 0.42645297 | L7: 0.35660349 | M7: 3.0283286
A8: Academic-funded only | B8: 8 | C8: 16 | D8: 0.42973111 | E8: 1.5368442 | F8: 25 | G8: 1.017667 | H8: 2.4153149 | I8: 0.87843198 | J8: 2.688757 | K8: 0.6690597 | L8: 0.28698865 | M8: 8.2299079
A9: Excluding industry-linked studies | B9: 11 | C9: 20 | D9: 0.41525458 | E9: 1.5147563 | F9: 25 | G9: 1.116789 | H9: 2.1202785 | I9: 1.0341726 | J9: 2.2186689 | K9: 0.56809713 | L9: 0.40380239 | M9: 5.6822019
A10: Industry-linked only | B10: 5 | C10: 11 | D10: 0.10582889 | E10: 1.1116316 | F10: 72.727273 | G10: 0.66859468 | H10: 2.1761606 | I10: 0.42824246 | J10: 2.8855731 | K10: 0.76823894 | L10: 0.10745037 | M10: 11.500425
A11: Packaging-only boundary | B11: 11 | C11: 20 | D11: 0.13446245 | E11: 1.1439217 | F11: 55 | G11: 0.84535385 | H11: 1.6012924 | I11: 0.78192619 | J11: 1.6735043 | K11: 0.56631765 | L11: 0.3062111 | M11: 4.2733815
A12: Per-volume functional unit only | B12: 14 | C12: 29 | D12: 0.22938983 | E12: 1.2578323 | F12: 44.827586 | G12: 0.94488797 | H12: 1.7355305 | I12: 0.88890093 | J12: 1.7798857 | K12: 0.60126369 | L12: 0.3278653 | M12: 4.8255855
A13: Europe only | B13: 11 | C13: 25 | D13: 0.21773504 | E13: 1.2432576 | F13: 40 | G13: 0.96883383 | H13: 1.5681186 | I13: 0.93345536 | J13: 1.6558794 | K13: 0.42660506 | L13: 0.46067305 | M13: 3.3552852
A14: Outside Europe or unknown | B14: 5 | C14: 6 | D14: 0.54037186 | E14: 1.7166451 | F14: 50 | G14: 0.7971844 | H14: 3.6965982 | I14: 0.51675964 | J14: 5.7025939 | K14: 0.96688741 | L14: 0.090685184 | M14: 32.49561
A15: Excluding single-use glass pairs | B15: 13 | C15: 20 | D15: -0.042069749 | E15: 0.9588029 | F15: 65 | G15: 0.71436343 | H15: 1.3462629 | I15: 0.66823741 | J15: 1.3757132 | K15: 0.5974609 | L15: 0.24833783 | M15: 3.7018243
A18: study_left_out | B18: short_name | C18: ratio
A19: S1 | B19: De Feo | C19: 1.3331989
A20: S2 | B20: Ferrara 23 | C20: 1.3525528
A21: S3 | B21: NAPCOR* | C21: 1.2840144
A22: S4 | B22: SDL | C22: 1.2581548
A23: S5 | B23: iPoint carton* | C23: 1.4529095
A24: S8 | B24: Stefanini | C24: 1.3608851
A25: S10 | B25: Amienyo | C25: 1.3422031
A26: S13 | B26: Ferrara 21 | C26: 1.4109419
A27: S14 | B27: c7-consult* | C27: 1.3719759
A28: S15 | B28: Wohner&Tacker | C28: 1.3630177
A29: S17 | B29: Simon | C29: 1.4228866
A30: S18 | B30: Bertolini | C30: 1.4485552
... A34: S7 | B34: TERI* | C34: 1.4358398

Sheet S5_PRISMA_log
A1: Screening counts behind fig0. Scoping counts are from an itemised web/database log; replace with database export counts before publication.
A3: stage | B3: n | C3: note
A4: identified | B4: 90 | C4: All unique records (scoping log 82 + team search and snowballing 8)
A5: identified_scoping | B5: 82 | C5: Itemised scoping search log (18 web and database searches plus UNEP 2020 and ACE 2020 reference lists); raw database hit counts to be replaced with exports
A6: identified_team | B6: 8 | C6: Team search and snowballing from Stefanini 2021 Table 1 and trade summaries (De Feo; NAPCOR; SDL thesis; iPoint; Gallego-Schmid; Pasqualino; Saleh; Mata & Costa)
A7: excluded_ta | B7: 38 | C7: 18 reviews (used for snowballing); 5 out-of-scope alternatives (bio-PET; PLA; tap water); 5 single format or end-of-life only; 4 medical or pharma; 3 transport packaging; 1 not a format comparison; 1 foodservice review; 1 not credible
A8: assessed | B8: 52 | C8: Full texts or open summaries assessed
A9: excluded_ft | B9: 8 | C9: 4 relative results or marketing claims only; 3 no extractable paired GWP; 1 duplicate data
A10: not_extractable | B10: 20 | C10: Eligible but paired numbers not openly available: 18 paywalled or not yet obtained (IFEU 2018 and 2020; Kouloumpis 2020; Kositcharoenkul 2024; Brock & Williams 2020 etc.); Ball/Sphera 2020 (bounds only); micro-brewery 2022 (relative only)
A11: included_reports | B11: 24 | C11: 24 reports = 23 studies (two Elopak reports treated as one study)

Sheet S6_Model_parameters
A1: parameter | B1: symbol | C1: low | D1: base | E1: high | F1: unit | G1: status | H1: source
A2: Primary aluminium cradle-to-gate | B2: V_Al | C2: 15.1 | D2: 15.1 | E2: 19.6 | F2: kg CO2e/kg | G2: sourced | H2: IAI 2022 global 15.1; India ~19.6 (LSE Grantham Institute)
A3: Recycled aluminium (gate-to-gate) | B3: S_Al | C3: 0.52 | D3: 0.52 | E3: 1 | F3: kg CO2e/kg | G3: sourced (low); high assumed | H3: IAI factsheet 0.52
A4: Aluminium recycling yield | B4: y_Al | C4: 0.9 | D4: 0.98 | E4: 0.98 | F4: fraction | G4: sourced | H4: TERI 2022 Table 15 (98%)
A5: Aluminium can-making overhead | B5: conv_Al | C5: 0.5 | D5: 1 | E5: 2 | F5: kg CO2e/kg | G5: assumed | H5: No source found - sensitivity range
